Workbook

Sheet 00_Overview_&_PRISMA
A1: AI-DRIVEN MODEL ENGINEERING: SYSTEMATIC LITERATURE REVIEW (SLR)
A3: 1. PRISMA 2020 Study Selection Matrix (Core Databases: N = 27 Included Studies)
A5: Database / Repository | B5: Records Identified (search hits) | C5: Retained after Title & Abstract (database interface) | D5: Records Logged for 2nd-Stage Screening | E5: Candidates after 2nd-Stage (logged, before de-dup) | F5: Included in Synthesis
A6: IEEE Xplore | B6: 318 | C6: 61 | D6: 83 | E6: 71 | F6: =COUNTIF(Final_Included_Studies!B2:B200,A6) -> 2
A7: SpringerLink | B7: 3093 | C7: 1192 | D7: 1050 | E7: 69 | F7: =COUNTIF(Final_Included_Studies!B2:B200,A7) -> 2
A8: ScienceDirect | B8: 1907 | C8: 126 | D8: 126 | E8: 13 | F8: =COUNTIF(Final_Included_Studies!B2:B200,A8) -> 9
A9: ACM Digital Library | B9: 2034 | C9: 23 | D9: 23 | E9: 10 | F9: =COUNTIF(Final_Included_Studies!B2:B200,A9) -> 6
A10: Scopus | B10: 140 | C10: 40 | D10: 40 | E10: 40 | F10: =COUNTIF(Final_Included_Studies!B2:B200,A10) -> 4
A11: Web of Science | B11: 93 | C11: 90 | D11: 90 | E11: 75 | F11: =COUNTIF(Final_Included_Studies!B2:B200,A11) -> 4
A12: Total Core SLR Corpus | B12: =SUM(B6:B11) -> 7585 | C12: =SUM(C6:C11) -> 1532 | D12: =SUM(D6:D11) -> 1412 | E12: =SUM(E6:E11) -> 278 | F12: =SUM(F6:F11) -> 27
A13: After de-duplication | D13: =D12-Dedup_Log!C47 -> 1366 | E13: 249
A14: Note: 'Included' counts each study under the database recorded in Final_Included_Studies. Four ACM studies (P04, P05, P06, P18) have no record in the ACM screening sheet and enter the PRISMA flow as 'identified via other methods'. Records Logged differs from Retained for IEEE Xplore (+22) and SpringerLink (−142); the 120-record net gap is shown in PRISMA_Flow.

Sheet Reconciliation_Summary
A1: FINAL RECONCILIATION — every location must agree on N and the PRISMA figures (FINAL_7)
A2: Location | B2: Value | C2: Expected | D2: Status | E2: Source / note
A3: 00_Overview_&_PRISMA — Included total (F12) | B3: ='00_Overview_&_PRISMA'!F12 -> 27 | C3: =PRISMA_Flow!C18 -> 27 | D3: =IF(B3=C3,"OK","MISMATCH") -> OK | E3: Formula
A4: PRISMA_Flow — Studies included in synthesis | B4: =PRISMA_Flow!C18 -> 27 | C4: =COUNTA(Final_Included_Studies!A2:A200) -> 27 | D4: =IF(B4=C4,"OK","MISMATCH") -> OK | E4: Formula
A5: PRISMA_Flow — Reconciliation check | B5: =PRISMA_Flow!C19 -> OK | C5: OK | D5: =IF(B5=C5,"OK","MISMATCH") -> OK | E5: Formula
A6: Final_Included_Studies — row count | B6: =COUNTA(Final_Included_Studies!A2:A200) -> 27 | C6: =PRISMA_Flow!C18 -> 27 | D6: =IF(B6=C6,"OK","MISMATCH") -> OK | E6: Formula
A7: Data Extraction — row count | B7: =COUNTA('Data Extraction'!A2:A200) -> 27 | C7: =PRISMA_Flow!C18 -> 27 | D7: =IF(B7=C7,"OK","MISMATCH") -> OK | E7: Formula
A8: Quality Assessment — row count | B8: =COUNTIF('Quality Assessment'!A3:A200,"P*") -> 27 | C8: =PRISMA_Flow!C18 -> 27 | D8: =IF(B8=C8,"OK","MISMATCH") -> OK | E8: Formula
A9: Study_Coding — row count | B9: =COUNTIF(Study_Coding!A3:A200,"P*") -> 27 | C9: =PRISMA_Flow!C18 -> 27 | D9: =IF(B9=C9,"OK","MISMATCH") -> OK | E9: Formula
A10: Maturity_Model — studies across Levels 1–6 | B10: =COUNT('Data Extraction'!AE2:AE200) -> 27 | C10: =PRISMA_Flow!C18 -> 27 | D10: =IF(B10=C10,"OK","MISMATCH") -> OK | E10: Formula
A11: Excluded_Records — rows | B11: =COUNTA(Excluded_Records!A2:A1000) -> 226 | C11: =PRISMA_Flow!C13+PRISMA_Flow!C15 -> 226 | D11: =IF(B11=C11,"OK","MISMATCH") -> OK | E11: Not retrieved + excluded with reasons
A12: Excluded_Records vs identified − included − earlier removals | B12: =COUNTA(Excluded_Records!A2:A1000) -> 226 | C12: =PRISMA_Flow!C3+PRISMA_Flow!C4-PRISMA_Flow!C18-PRISMA_Flow!C5-PRISMA_Flow!C7-PRISMA_Flow!C9-PRISMA_Flow!C11 -> 226 | D12: =IF(B12=C12,"OK","MISMATCH") -> OK | E12: 7,585 + 4 − N − 6,053 (title/abstract) − 120 (not logged) − 46 (duplicates) − 1,117 (2nd stage)
A13: Report — Figure 1 (PRISMA diagram) N | B13: 27 | C13: =PRISMA_Flow!C18 -> 27 | D13: =IF(B13=C13,"OK","MISMATCH") -> OK | E13: PRISMA 2020 diagram drawn from PRISMA_Flow; note states retrospective de-duplication
A14: Report — narrative 'N =' mentions (all 6) | B14: 27 | C14: =PRISMA_Flow!C18 -> 27 | D14: =IF(B14=C14,"OK","MISMATCH") -> OK | E14: All 'N =' mentions in SLR_AI_Driven_Model_Engineering_FINAL_7.docx read 27 (scripted check)
A15: Report — Table 5 year total / database total | B15: 27 | C15: =PRISMA_Flow!C18 -> 27 | D15: =IF(B15=C15,"OK","MISMATCH") -> OK | E15: Table 5 in SLR_AI_Driven_Model_Engineering_FINAL_7.docx
A16: Report — abstract N | B16: 27 | C16: =PRISMA_Flow!C18 -> 27 | D16: =IF(B16=C16,"OK","MISMATCH") -> OK | E16: Abstract states 27 primary studies
A18: PRISMA figures used everywhere: 7,585 identified; 6,053 excluded at title/abstract; 1,532 retained; 120 not logged; 1,412 logged; 46 duplicates; 1,366 unique; 1,117 excluded at 2nd stage (EC1 667, EC2 153, EC4 176, EC5 110, EC8 11); 249 sought; 222 not retrieved; 27 assessed; 4 excluded with reasons; 4 via other methods; N = 27.
A20: Report — Figure 3 bands vs Stage_Coverage | B20: match | C20: match | D20: =IF(B20=C20,"OK","MISMATCH") -> OK | E20: 12 stage bands recomputed; figure regenerated from this sheet
A21: Report — body page count (Introduction → before References) | B21: 27 | C21: 30 | D21: =IF(B21<=C21,"OK","MISMATCH") -> OK | E21: ≤ 30 required; total PDF 33 pp incl. cover/declaration (3) and references (3)
A22: Report — excluded studies (P16, P20, P23, P26, P29, P31, P34) cited only in Appendix B | B22: Appendix B only | C22: Appendix B only | D22: =IF(B22=C22,"OK","MISMATCH") -> OK | E22: Each has a reference-list entry; none is used as evidence in sections 3–8

Sheet IEEE Xplore
A1: IEEE Xplore screening log | B1: Database | C1: Reviewer(s) | D1: Title | E1: Authors | F1: Year | G1: Venue | H1: DOI / Link | I1: Abstract (paste) | J1: Reviewer 1 | K1: Reviewer 1 Decision | L1: Reviewer 2 | M1: Reviewer 2 Decision | N1: Final Decision | O1: Exclusion Reason (if excluded)
A2: 1 | B2: IEEE Xplore | C2: Phindile Mposwa, Sibongiseni Tsitsa | D2: A Catalogue of Model Smells and Refactoring Operations for Object-Oriented Software | E2: Brahmaleen K. Sidhu,Kawaljeet Singh,Neeraj Sharma | F2: 2018 | G2: Proceedings of the 2nd International Conference on Inventive Communication and Computational Technologies (ICICCT | H2: https://doi.org/10.1109/ICICCT.2018.8473027 | I2: The advent of Model Driven Engineering has observable behaviour. promoted software quality assurance activities to a higher level Model Driven Engineering (MDE) is being increasingly of abstraction than code, i.e. architectural models. Early adopted in development of complex software systems used quality assessment facilitates better design, reduces in high-reliability domains like aviation, automotive, maintenance costs, manages requirement volatility and leads to aerospace, and other embedded systems [3]. Model Driven faster software development. Less than optimal design decisions made during development and subsequent evolution Development (MDD2) is a model-pivoted development introduce smells in the software. Model Refactoring uncovers paradigm. MDD is followed by Architecture-Driven smells at architectural level and transforms graphical Modernization (ADM), which is a two-step evolutionary, representations of software to enhance design without affecting platform and language-independent maintenance paradigm. its observable behaviour. Focusing on object-oriented software Firstly, a model instance is created by reverse engineering systems, this paper presents a catalogue of smells and source code. This model is successively transformed to refactoring operations for UML class diagrams. The paper concludes by highlighting challenges in model refactoring and reach a higher abstraction level called Knowledge Discovery the potential of learning-based approach in automating the Metamodel (KDM3) [4]. The problems found in the target process. legacy system are solved by applying refactorings and optimizations at this level. In the second step, forward | J2: Phindile Mposwa | K2: Include | L2: Sibongiseni Tsitsa | M2: Include | N2: Include | O2: Included: addresses software/systems modelling; reverse engineers models from code
A3: 2 | B3: IEEE Xplore | C3: Phindile Mposwa, Sibongiseni Tsitsa | D3: A Comparative Study of Large Language Models for Model-Driven Reverse Engineering | E3: Faculty of Sciences and Techniques of Errachidia, UMI Faculty of Sciences and Techniques of Errachidia, UMI | F3: 2026 | H3: A Comparative Study of Large Language Models for Model-Driven Reverse Engineering | I3: The extraction of abstract models from the source In practice, many software systems were developed without codeisoneofthemainfocusesofmodel-drivenreverseengineer- explicit models or with models that are no longer maintained, ingandisparticularlyimportantforlegacysystems,whichdonot especially legacy systems [2]. As a result, understanding, have updated documentation. Recovering abstract models from evolving,ormodernizingsuchsystemsoftenrequiresrecover- legacy systems is complex, given that the technical constructs combinedwithdomain-levelconstructsareimplementedthrough ing high-level domain abstractions directly from source code. multiple layers of technology and system-specific rules. Current This recovery task is difficult because domain concepts are static analysis and heuristic-based approaches can struggle to coupled with technical infrastructure, framework code, and separatetheseconcerns.Therecentemergenceoflargelanguage platform-specific details [3]. models (LLMs) is promising with regard to modeling software, Recovering a PIM from existing code is more challenging but behaviors and expected outcomes related to LLMs when performing reverse engineering tasks are challenging. This pa- than forward modeling because the original domain intent per compares the performance of various LLMs on a reverse is not explicitly represented. Reverse engineering must infer engineeringtaskrelatedtotherecoveryofabstractmodelsfrom abstractions that were never formally modeled and must dis- the source code. This comparison aims to identify the domain tinguish between domain-relevant concepts and purely tech- constructs represented through an intermediate representation nical constructs. Existing model-driven reverse engineering of the source code. Three LLMs, namely ChatGPT, Claude, and Meta AI, were assessed on the same input representation, with (MDRE) approaches rely heavily on static analysis artifacts, each LLM performing the task of recovering abstract models such as abstra | J3: Phindile Mposwa | K3: Include | L3: Sibongiseni Tsitsa | M3: Include | N3: Include | O3: Included: applies AI to reverse engineering/code-to-model extraction; applies AI within model-driven engineering context
A4: 3 | B4: IEEE Xplore | C4: Phindile Mposwa, Sibongiseni Tsitsa | D4: A Digital Twin Modeling Code Generation Framework based on Large Language Model | E4: School of Automation Science and Electrical Engineering School of Automation Science and Electrical Engineering | H4: https://doi.org/10.1109/IECON55916.2024.10905976 | I4: Digital twin has made significant achievements in implementationstepsofdigitaltwintechnology[3].However, applications across various fields by bridging the gap between the process of digital twin modeling faces some challenges virtualandphysicalworld.However,themodelingofdigitaltwin summarized as follows. faces challenges of labor-intensive and time-consuming manual modeling or coding. With the emergence of artificial intelligence (1) Manual labor-intensive modeling: Current modeling foundation models, the integration of large language models software offers a method of manual manipulation, allow- (LLMs) and digital twin may contribute to enhancing modeling ing users to create detailed models by drag-and-drop and efficiency significantly. Therefore, in this paper, a framework interactivemodeling.However,thisprocessisoftenlabor- of digital twin modeling code generation is proposed based on LLMs.Giveninstructionsinnaturallanguageprompts,modeling intensive and time-consuming. code in digital twin software will be generated from LLMs. (2) High level of expertise for coding: Alternatively, some Firstly,atreediagram-basedcodegenerationmethodisproposed software enables users to generate modeling scenes di- to generate main section of modeling code. Additionally, a rectlybycodinganddebugging.Whilethisapproachcan randomized code completion method is proposed to complete be more efficient, it requires a high level of expertise, missing parts which are unspecified or unclear in prompts. Finally,acasestudyisgiveninNVIDIAOmniverseforadigital making it difficult for newcomers to adopt. twin construction based on framework proposed in this paper. (3) HallucinationscausedbyAIGCmodels:Emergingtech- IndexTerms—digitaltwin,largelanguagemodel,modelingand nologies empowered by artificial intelligence generated simulation, code generation, AI foundation model content (AIGC) technologies, like text-to-3D, allow for the rapid generation of 3D models through generative | J4: Phindile Mposwa | K4: Include | L4: Sibongiseni Tsitsa | M4: Include | N4: Include | O4: Included: applies identifiable AI technique; supports model-to-code synthesis
A5: 4 | B5: IEEE Xplore | C5: Phindile Mposwa, Sibongiseni Tsitsa | D5: A Federated Adaptive Large Language Model Fine-Tuning Framework for Software Development | F5: 2025 | H5: https://doi.org/10.1109/TSC.2025.3623626 | I5: Large Language Models (LLMs) have achieved re- stronger performance across a wide spectrum of NLP tasks, markableprogressincodeintelligencetasks,significantlyenhanc- includingmachinetranslationandquestionanswering[2],[3]. ingtheefficiencyofsoftwaredevelopment.However,severalchal- Recognizing that source code possesses structural and seman- lengesremain.First,fine-tuningLLMsforspecifictasksrequires tic characteristics analogous to natural language, researchers alargeamountoftask-specificlabeleddata,whichisoftencostly and time-consuming to acquire. Second, due to the sensitivity of haveextendedLLMstocode-relatedapplications,suchascode code data, high-quality internal datasets from different organi- generation,summarization,andtranslation[4].Theemergence zations cannot be directly shared or combined for fine-tuning. of code-oriented LLMs has further accelerated the paradigm Moreover, variations in programming languages across organi- shift toward Software 3.0, an era in which AI models can zationscanintroduceinterferenceduringthefine-tuningprocess. autonomouslyassist—orevenlead—softwareengineeringpro- Toaddressthesechallenges,weproposeF-CodeLLM,afederated adaptive large language model fine-tuning framework designed cesses[5].Despitetheimpressivezero-shotandfew-shotgen- forreal-worldsoftwaredevelopmentscenarios.Tothebestofour eralization capabilities of general-purpose LLMs, their perfor- knowledge,thisisthefirstapproachtoapplyfederatedlearningto mance often lags behind task-specific fine-tuned models [6]. thefine-tuningofcodeLLMs,enablingcollaborativemodelopti- For example, models such as CodeX tend to underperform mizationwhilepreservingtheprivacyofeachorganization’scode on domain-specific programming languages like SQL, which data.WedesignanefficientLLMfine-tuningmethodtomitigate the computational and communication overhead associated with contains multiple dialects that general LLMs are typically not collaborative fine-tuning. Experimental results demonstrate that t | J5: Phindile Mposwa | K5: Exclude | L5: Sibongiseni Tsitsa | M5: Exclude | N5: Exclude | O5: Excluded: Discusses AI for code/software tasks but does not address software model engineering (no UML, BPMN, DSL, metamodel, or model transformation involved)
A6: 5 | B6: IEEE Xplore | C6: Phindile Mposwa, Sibongiseni Tsitsa | D6: A Generic Metamodel for Cognitive-Affective Training of Users Using Serious Games | E6: GIDITIC, Universidad EAFIT GIDITIC, Universidad EAFIT GIDITIC, Universidad EAFIT, Colombia | F6: 2023 | H6: https://doi.org/10.1109/CLEI60451.2023.10346132 | I6: Model-Driven Engineering can play a crucial emotions [7], [8]. This definition of the metamodel allows role in developing serious training games. Model-Driven its instantiation. Besides, it is an advance regarding the Engineering benefits the creation of serious games by offering automatic code generation using each component of the a structured software modeling approach, resulting in cognitive-affective metamodel. enhanced productivity, quality, and maintainability of the The main objective of our research is to define and game software. These models can then be used to validate the cognitive-affective metamodel using a automatically generate code and other artifacts, significantly modeling tool. To formalize the metamodel, we conducted reducing development time and improving efficiency. We propose a metamodel that describes users' cognitive and several activities, including designing the model in Eclipse affective dimensions during a serious game, utilizing a set of Modeling Framework (EMF), defining semantics and classes that define the relationships between them based on a creating instances. To validate our metamodel, we use theoretical framework of cognitive functions and emotions. examples. We employed the Eclipse Modeling Framework to transform This work uses documentary research to explore the a primary model of the problem domain into a metamodel. metamodeling tools for automatic code generation. First, We then combine the cognitive and affective dimensions of the we conduct a descriptive analysis to compare model and formalize it into a generic metamodel for cognitive- metamodeling frameworks and select an MDE tool for affective training of users using serious games. Finally, we designing the cognitive-affective metamodel. We then use illustrate our approach with an example of instantiation of the model metamodel. We concluded with the importance of the MDE tool to design and validate the metamodel and Model-Driven Engineering in serious game development | J6: Phindile Mposwa | K6: Include | L6: Sibongiseni Tsitsa | M6: Include | N6: Include | O6: Included: addresses software/systems modelling; supports model-to-code synthesis
A7: 6 | B7: IEEE Xplore | C7: Phindile Mposwa, Sibongiseni Tsitsa | D7: A Metamodel for a DSL to Design Decision Support Systems in Smart Tourism | E7: Charaf Ouaddi, Lamya Benaddi, Adnane Souha, Lahbib Naimi, El mahi Bouziane and Abdeslam Jakimi∥ | F7: 2024 | H7: https://doi.org/10.1109/DASA63652.2024.10836366 | I7: ThedevelopmentofDecisionSupportSystems(DSS) Tourism, where decisions need to be made quickly based on for several companies operating in sectors such as tourism, real-time data. healthcare, or others, presents significant challenges due to the One solution to simplify and speed up the development of nature of their multi-component architecture. A typical DSS DSS is the use of Domain-Specific Languages (DSLs). DSLs consists of a data component, a model component incorporating machine learning and deep learning techniques, and a user arespecializedlanguagesdesignedforaspecificfield.InDSS interfacecomponent,eachonerequiresdiversetechnologies.This development,theycanbeusedtocreatemodelsandtemplates, complexity increases development time and effort, hindering the and automatically generate parts of the system’s code. By efficient design of DSS tailored to specific domains like tourism, using DSLs, developers can reduce the effort needed to build where real-time decision-making is essential. One promising ap- a DSS and make the process faster and more efficient. proachtoovercomethesechallengesistheuseofDomain-Specific Languages(DSLs).DSLsallowdeveloperstomodelandgenerate Several studies have proposed DSLs to simplify the de- code more efficiently by providing high-level abstractions suited velopment of applications such as mobile apps [6], websites to the domain. By leveraging DSLs, it is possible to simplify the [7], and chatbots [8]–[11]. These DSLs have been built using design process and automate the generation of code or parts metamodels and Frameworks like EMF (Eclipse Modeling of the DSS, thereby reducing the overall complexity and time Framework) which is widely used to create and edit the required for development. This paper proposes a metamodel for designing DSS, specifically for the Smart Tourism sector. The metamodel of a DSL. metamodel serves as a foundation for the creation of DSL. The The aim of this work is to propose a metamodel for de- goalistoprovideaso | J7: Phindile Mposwa | K7: Include | L7: Sibongiseni Tsitsa | M7: Include | N7: Include | O7: Included: addresses metamodel engineering with AI; applies AI to domain-specific language/model engineering
A8: 7 | B8: IEEE Xplore | C8: Phindile Mposwa, Sibongiseni Tsitsa | D8: A Review of Screenshot-to-Code Generation Systems | E8: Software Engineer, PayPal, USA VP Technology & Consulting, Rocket, USA | F8: 2026 | G8: Proceedings of the 5th International Conference on Communication, Computing and Electronics Systems (ICCCES-2026) | I8: The conversion of screenshots into source code is very than other development jobs. Moreover, the user interface important phase in the automation of user interface consumes 50% of the development time, while it accounts for development. There are artificial-based tools which can 48% of the code for the software on average [4]. understand images and further convert them into executable source code. These system’s performance is further improved In software development, screenshot to code creation with the incorporation of generative artificial intelligence. These becomes more and more crucial, particularly with the generative artificial intelligence-based systems achieve high application of artificial intelligence (AI) and machine accuracy in converting sketches into source code. Further these learning (ML) [5]. Iterative prototyping is used in the design systems are helpful for developers, otherwise it was time consuming and costly to convert images into source code and of GUIs, beginning with the creative method of creating developers often distracted from focusing on logic and drawings, which are basic handmade representations. It is a functionality. This review paper presents the existing studies useful pictorial method for quickly, easily, and affordably which generate source code from sketches using artificial communicating ideas, discussing them, and comparing intelligence and machine learning. In this paper, several studies various options. In the screenshot to code generation process, are evaluated and compared based on different parameters. Sketches are used to develop wireframes, which specify the Their strengths and weaknesses are also discussed in this paper. order of appearance and depict the framework and This review paper will help the researchers and authors working arrangement of the user interface, excluding any graphical in this area to further improve GUI design process and in elements like colors or pictures [6-8]. The design of the development | J8: Phindile Mposwa | K8: Include | L8: Sibongiseni Tsitsa | M8: Include | N8: Include | O8: Included: applies identifiable AI technique; supports model-to-code synthesis
A9: 8 | B9: IEEE Xplore | C9: Phindile Mposwa, Sibongiseni Tsitsa | D9: A Survey of Domain-Specific Fine-Tuned Large Language Models | E9: MobileInnovationsCorporation,NiagaraFalls,ONLGM,Canada | F9: 2026 | H9: https://doi.org/10.1109/ACCESS.2026.3658096 | I9: The advancement of large language models (LLMs), such as GPT-3, BERT, and Llama, has introduced a new era in natural language processing (NLP) as they have demonstrated exceptional capabilitiesacrossdiversetasks.Fine-tuningtheseLLMswithdomain-specificdatahasbecomeapopular practice,particularlyindomainslikeeducation,law,medicine,andsoftwaredevelopment.Thisprocessnot onlyempowersLLMswithdomainknowledgebutalsoenhancestheircapabilitiesbyaddressingissuessuch asreliabilityandreducingthechanceofhallucination.Thissurveyexaminesarangeofdomain-specificfine- tunedmodelsbyhighlightingtheiruniquecharacteristics,enhancementsinperformance,andthechallenges theyaddress,includingthedemandforextensivecomputationalresources.Furthermore,weexplorethefine- tuningmethodologies,includinginstructiontuningusedinthedevelopmentofthesemodels,andultimately, inform future research on the existing gaps and how to enhance the effective application of LLMs across diversedomains. INDEXTERMS Fine-tuning,fine-tunedlargelanguagemodels,largelanguagemodels,LLM. | J9: Phindile Mposwa | K9: Exclude | L9: Sibongiseni Tsitsa | M9: Exclude | N9: Exclude | O9: Excluded: Discusses AI for code/software tasks but does not address software model engineering (no UML, BPMN, DSL, metamodel, or model transformation involved)
A10: 9 | B10: IEEE Xplore | C10: Phindile Mposwa, Sibongiseni Tsitsa | D10: Accurate and Consistent Graph Model Generation from Text with Large Language Models | E10: Accurate and Consistent Graph Model Generation | F10: 2025 | H10: https://doi.org/10.1109/MODELS67397.2025.00018 | I10: Graphmodelgenerationfromnaturallanguagede- prioritizes generating models that accurately reflect such tex- scriptionisanimportanttaskwithmanyapplicationsinsoftware tualdescription,ignoringanyconstraints.Althoughsyntactical engineering. With the rise of large language models (LLMs), correctness is typically addressed in both cases, ensuring there is a growing interest in using LLMs for graph model bothaccuracyandconsistencyiscriticalforeffectivelyutiliz- generation. Nevertheless, LLM-based graph model generation typicallyproducespartiallycorrectmodelsthatsufferfromthree ing generated models in subsequent model-driven automation main issues: (1) syntax violations: the generated model may not processes, such as code generation [12] and model-based adhere to the syntax defined by its metamodel, (2) constraint testing [13]. Therefore, jointly considering both the accuracy inconsistencies: the structure of the model might not conform and consistency of models generated by LLMs is essential. to some domain-specific constraints, and (3) inaccuracy: due Problemstatement.DuetotheintrinsiclimitationsofLLMs, to the inherent uncertainty in LLMs, the models can include inaccurate, hallucinated elements. While the first issue is often the models they generate are typically partially correct and addressed through techniques such as constraint decoding or may exhibit issues in all three aspects: (1) syntax: the filtering, the latter two remain largely unaddressed. Motivated textual representation of the model may violate the syntax by recent self-consistency approaches in LLMs, we propose specified by the metamodel; (2) consistency: the structure a novel abstraction-concretization framework that enhances the of the graph model may conflict with domain-specific well- consistencyandqualityofgeneratedgraphmodelsbyconsidering multipleoutputsfromanLLM.Ourapproachfirstconstructsa formedness constraints [11]; and (3) quality: the generated probabilisticpartialmodelthataggregatesallcandidat | J10: Phindile Mposwa | K10: Include | L10: Sibongiseni Tsitsa | M10: Include | N10: Include | O10: Included: applies AI to model generation; addresses metamodel engineering with AI; applies AI within model-driven engineering context
A11: 10 | B11: IEEE Xplore | C11: Phindile Mposwa, Sibongiseni Tsitsa | D11: Aligning Crowd-Sourced Human Feedback for Reinforcement Learning on Code Generation by Large Language Models | F11: 2024 | G11: 4104 IEEETRANSACTIONSONBIGDATA,VOL.XX,NO.X,NOVEMBER2023 1 | H11: https://doi.org/10.1109/TBDATA.2024.3524104 | I11: This paper studies how AI-assisted programming program compared to how experienced programmers analyze and large language models (LLM) improve software developers’ acodesnippetonalgorithms?Withthegrowingavailabilityof ability via AI tools (LLM agents) like Github Copilot and extensive data, a key question arises: How can we effectively Amazon CodeWhisperer, while integrating human feedback to leverage unsupervised machine learning in combination with enhance reinforcement learning (RLHF) with crowd-sourced computationtoenhancetext-to-codegeneration.Additionally,we the naturalness hypothesis, while integrating human feedback demonstratethatourBayesianoptimizationframeworksupports through human-in-the-loop computation, to enhance and eval- AI alignment in code generation by distributing the feedback uate LLMs and LLM agents? collection burden, highlighting the value of collecting human Human-in-the-loop computation has the potential to greatly feedbackofgoodquality.Ourempiricalevaluationsdemonstrate improvethereadability,reliability,andtestabilityofgenerated the efficacy of this approach, showcasing how LLM agents can be effectively trained for improved text-to-code generation. Our code,whileeffectivelyaddressingAIalignmentissuesincode Bayesian optimization framework can be designed for general generation [15], [16], [17], [18]. The AI alignment challenge domain-specific languages, promoting the alignment of large inLLM-basedcodegenerationinvolvesensuringthatthegen- language model capabilities with human feedback in AI-assisted erated code meets requirements and is executable. LLMs may programming for code generation. prioritizefluencyoveraccuracy,producingcodethatcompiles | J11: Phindile Mposwa | K11: Include | L11: Sibongiseni Tsitsa | M11: Include | N11: Include | O11: Included: applies AI to model transformation; applies AI to domain-specific language/model engineering
A12: 11 | B12: IEEE Xplore | C12: Phindile Mposwa, Sibongiseni Tsitsa | D12: AskIt Unified Programming Interface for Programming with Large Language Models | E12: Amagasaki, Japan | F12: 2024 | H12: https://doi.org/10.1109/CGO57630.2024.10444830 | I12: Large Language Models (LLMs) exhibit a unique The rise of these emergent abilities holds significant im- phenomenonknownasemergentabilities,demonstratingadeptness plications for software development, potentially altering the across numerous tasks, from text summarization to code genera- very methods by which software is crafted. Developers can tion. While these abilities open up novel avenues in software incorporate LLMs within applications to handle tasks such as design and crafting, their incorporation presents substantial challenges. Developers face decisions regarding the use of LLMs questionanswering,textsummarization,orlanguagetranslation. for directly performing tasks within applications as well as Another application of LLMs is in code generation. Tools like for generating and executing code to accomplish these tasks. Jigsaw [13] and Codex/Copilot [8] harness LLMs to convert Moreover, effective prompt design becomes a critical concern, natural language descriptions into code. Even without these given the necessity of extracting data from natural language specific tools, developers can leverage LLM-based chatbots, outputs. To address these complexities, this paper introduces AskIt, a domain-specific language (DSL) specifically designed for like ChatGPT based on GPT-4 [14], BingAI, and Bard, for the LLMs. AskIt simplifies LLM integration by providing a unified same purpose. interface that not only allows for direct task execution using However, integrating LLMs into software development is LLMs but also supports the entire cycle of code generation and not without challenges. One primary decision developers face execution. This dual capability is achieved through (1) type- is whether to embed the LLM directly into the application or guided output control, (2) template-based function definitions, and (3) prompt generation for both usage modes. Our evalua- employ it for code generation. The distinction between these tions underscore AskIt’s effectiveness. Across | J12: Phindile Mposwa | K12: Include | L12: Sibongiseni Tsitsa | M12: Include | N12: Include | O12: Included: applies AI to domain-specific language/model engineering
A13: 12 | B13: IEEE Xplore | C13: Phindile Mposwa, Sibongiseni Tsitsa | D13: Augmenting the Generality and Performance of Large Language Models for Software Engineering | E13: Augmenting the Generality and Performance of | F13: 2025 | G13: 2025 IEEE/ACM 47th International Conference on Software Engineering: Companion Proceedings (ICSE-Companion) | H13: https://doi.org/10.1109/ICSE-Companion66252.2025.00059 | I13: Large Language Models (LLMs) are revolutioniz- researchers have also been concerned with building and eval- ing software engineering (SE), with special emphasis on code uatingLLMsacrossabroaderrangeofSEtasks,ashighlighted generation and analysis. However, their applications to broader in recent surveys [13]–[15]. Despite the variety of datasets, SEpracticesincludingconceptualization,design,andothernon- networkarchitectures,modelsizes,prompting,andfine-tuning code tasks, remain partially underexplored. This research aims to augment the generality and performance of LLMs for SE by techniques documented in these surveys, there is a high (1) advancing the understanding of how LLMs with different imbalancetowardcoding-relatedtasks.Furthermore,thereare characteristicsperformonvariousnon-codetasks,(2)evaluating no works focused on evaluating the foundational knowledge themassourcesoffoundationalknowledgeinSE,and(3)effec- (i.e., factual and conceptual knowledge [16]) of LLMs in SE. tively detecting hallucinations on SE statements. The expected Building on the ideas presented in [17], [18] regarding the contributions include a variety of LLMs trained and evaluated on domain-specific datasets, new benchmarks on foundational level of applicability that LLMs can potentially achieve, to knowledgeinSE,andmethodsfordetectinghallucinations.Initial effectively support SE practitioners in real-world scenarios, results in terms of performance improvements on various non- a certain level of generality (i.e., range of supported tasks) code tasks are promising. andperformancearerequired.Tosatisfythisdualneed,tothe | J13: Phindile Mposwa | K13: Exclude | L13: Sibongiseni Tsitsa | M13: Exclude | N13: Exclude | O13: Excluded: Discusses AI for code/software tasks but does not address software model engineering (no UML, BPMN, DSL, metamodel, or model transformation involved)
A14: 13 | B14: IEEE Xplore | C14: Phindile Mposwa, Sibongiseni Tsitsa | D14: Automated Business Process Model Generation with Large Language Models A Systematic Literature Review | E14: recently attracted growing attention at the intersection of Business Process Management (BPM), Natural | F14: 2026 | G14: IEEE Access. This is the author's version which has not been fully edited and | H14: https://doi.org/10.1109/ACCESS.2026.3723936 | I14: Theautomatedgenerationofbusinessprocessmodelsfromnaturallanguagedescriptionshas recently attracted growing attention at the intersection of Business Process Management (BPM), Natural Language Processing (NLP), and Large Language Models (LLMs). This paper presents a Systematic Literature Review (SLR) on the current state of research in this emerging field. Following the guidelines of Kitchenham et al. and the PRISMA framework, 29 studies published between January 1st, 2023 and March10th,2026wereidentified,selected,andanalyzed. Thereviewaddressestworesearchquestionsfocusingontheappliedmethodologicalapproaches,theused LLMs, the employed modeling languages, as well as the evaluation strategies, challenges, and limitations reportedintheliterature.TheresultsshowaclearshiftfromtraditionalNLP-basedtechniquestowardLLM- onlyandhybridapproaches.OpenAI’sGPTfamily,especiallyGPT-4anditsvariants,dominatesthefield, while BPMN is by far the most frequently used target process modeling language. Furthermore, existing studies evaluate automated process model generation primarily through output-focused methods, such as quantitativemetrics,expertreviews,andcomparisonswithalternativeorhuman-createdprocessmodels. Atthesametime,thereviewedstudiesrevealimportantchallenges,includingthecontinuedneedforhuman involvementandtheoutputquality.Overall,currentapproachesshowstrongpotential,buttheystillactmore asintelligentassistantsthanasfullyautonomousprocessmodelers. | J14: Phindile Mposwa | K14: Include | L14: Sibongiseni Tsitsa | M14: Include | N14: Include | O14: Included: applies AI to model generation; applies AI to BPMN/process model engineering
A15: 14 | B15: IEEE Xplore | C15: Phindile Mposwa, Sibongiseni Tsitsa | D15: Automated Classification of Metamodel Repositories A Machine Learning Approach | E15: Phuong T. Nguyen, Juri Di Rocco, Ludovico Iovino | F15: 2019 | H15: https://doi.org/10.1109/MODELS.2019.00011 | I15: Manualclassificationmethodsofmetamodelreposi- strictly depends on the chosen similarity measure. Structural toriesrequirehighlytrainedpersonnelandtheresultsareusually similarities, which generally offer better accuracy, have poorer influencedbythesubjectivityofhumanperception.Therefore,au- performancewhencomparedwithtraditionallexicaltechniques, tomatedmetamodelclassificationisverydesirableandstringent. including cosine similarity [7] and dice coefficient [19] that in Inthiswork,MachineLearningtechniqueshavebeenemployed for metamodel automated classification. In particular, a tool contrast have limited accuracy [5]. implementing a feed-forward neural network is introduced to Machine Learning (ML) algorithms attempt to simulate classify metamodels. An experimental evaluation over a dataset humans’ learning activities, aiming to acquire real-world of 555 metamodels demonstrates that the technique permits to knowledge autonomously [41]. In this way, ML systems learn from manually classified data and effectively categorize are capable of generalizing from concrete examples, without incomingunlabeleddatawithaconsiderablyhighpredictionrate: thebestperformancecomprehends95.40%assuccessrate,0.945 needing to be manually programmed [21]. Thanks to this as precision, 0.938 as recall, and 0.942 as F1 score. characteristic, ML algorithms find their applications in various domains, including web search by learning from a user’s long- | J15: Phindile Mposwa | K15: Include | L15: Sibongiseni Tsitsa | M15: Include | N15: Include | O15: Included: addresses metamodel engineering with AI
A16: 15 | B16: IEEE Xplore | C16: Phindile Mposwa, Sibongiseni Tsitsa | D16: Automating Code Generation for MDE using Machine Learning | E16: King’s College London, Strand, | F16: 2023 | G16: 2023 IEEE/ACM 45th International Conference on Software Engineering: Companion Proceedings (ICSE-Companion) | H16: https://doi.org/10.1109/ICSE-Companion58688.2023.00060 | I16: The overall aim of our research is to improve the quality conditions, such as low complexity and redundancy, techniquesforsynthesizingcodegeneratorsintheModel-Driven high efficiency, etc. Engineering(MDE)context.Codegenerationisoneofthemain We aim to address this problem by automating the pro- elementsofModel-DrivenEngineering,involvingtransformation duction of code generators from examples, by using AI from specification models to produce executable code. A code generatorisdesignedtoreducethemanualprogramconstruction techniques, particularly symbolic machine learning (ML). work used to implement a software system, but building a code generator itself still currently needs much manual effort. II. RESEARCHHYPOTHESIS Meanwhile, existing code generators are typically not flexible to Our research hypothesis is that symbolic machine learning adjust for changing development requirements and are hard to canbeusedtolearncodegeneratorrulesfromexamples,ina reuse for different target languages. Therefore,weaimtoprovidetechniquestoimprovetheprocess way that enables the effective creation of code generators. of building code generators, and let them be more reusable. Currently, we researched the related new and traditional ap- III. STATEOFTHEART proachesforgeneratingcodeandprojectsusingAIforprogram Related work includes the mainstream MDE code gener- translation, code completion or program generation. Based on ation techniques of model-to-text, model-to-model and text- thisresearchwedecidedtofocusonasymbolicmachinelearning methodrelatedtotheprogramming-by-exampleconcepttobuild to-text transformation approaches, and more novel AI-based code generators. We use this “Code Generation By Example” program translation and code completion approaches. (CGBE) concept with tree-to-tree structure mappings as the information format. CGBE has good performance in terms of A. MDE Approaches trainingdatasetsizeandtimewhenappliedtolearningaUML- Model-to-Model (M2M) code generation approaches use | J16: Phindile Mposwa | K16: Include | L16: Sibongiseni Tsitsa | M16: Include | N16: Include | O16: Included: applies AI to UML/software model artefacts; applies AI within model-driven engineering context
A17: 16 | B17: IEEE Xplore | C17: Phindile Mposwa, Sibongiseni Tsitsa | D17: Automating Feature Requests for User-Driven Model Evolution at Runtime | E17: Dresden, Germany | F17: 2023 | G17: IEEE International Conference on Model Driven Engineering Languages and Systems Companion (MODELS-C) | H17: https://doi.org/10.1109/MODELS-C59198.2023.00149 | I17: As software projects progress, requirements can isimplementedbythedevelopmentteamandbecomespartof change and diverge between individual users. This happens in thenextrelease.Thisincrementalevolutionprocessisthestate particularinconsumersoftware.Subsequently,themaintenance of the art in software development. Because this process is ofsuchsoftwarebecomesacomplexandresource-intensivetask. complexandinvolvesdifferentpeople,errorscanhappenalong However, system parts can be modified and individualized at runtime if domain-specific evolution and configuration tasks the way. A request can be forgotten, ambiguously described, are transferred to the user. This reduces development efforts andthusfalselyrejectedormisunderstood.Theoverallprocess andcontributestosustainableandlong-livingsoftwareproducts may also take too long to deliver the feature in time. The calledeternalsoftware.Inmodel-drivenengineering,atargetfor workforce requirement and ineffective manual management this evolution is the domain’s metamodel. The adaptive object work make this process unsustainable. modelarchitecturestyleisaknownapproach,enablingvariable metamodelsatruntime.However,specifyingtransformationsfor Looking at the state of the art in research, system adaption evolving the metamodel can be challenging, particularly for and evolution at runtime became an established area over end-users. Editor-based solutions are complex to develop and the last two decades. This research involves different fields require multiple user interactions to achieve a desired change. and disciplines, such as Dynamic Software Product Lines [4], We propose a new approach based on textual feature requests the application of techniques from Model Driven Architec- from community-driven software development to address this issue.Wedefinealanguageforfeaturerequeststhattargetmodel ture at runtime [5]–[7], models@run.time [8], and Adaptive evolution.Wedefinethislanguageontopofformaldeltamodels. Object Models (AOM) [9], [10]. Conseq | J17: Phindile Mposwa | K17: Include | L17: Sibongiseni Tsitsa | M17: Include | N17: Include | O17: Included: addresses software/systems modelling
A18: 17 | B18: IEEE Xplore | C18: Phindile Mposwa, Sibongiseni Tsitsa | D18: BPMN-LLM Transforming BPMN Models Into Smart Contracts Using Large Language Models | F18: 2025 | G18: 2025 IEEE. All rights reserved, | H18: https://doi.org/10.1109/MS.2025.3553293 | J18: Phindile Mposwa | K18: Include | L18: Sibongiseni Tsitsa | M18: Include | N18: Include | O18: Included: applies AI to BPMN/process model engineering
A19: 18 | B19: IEEE Xplore | C19: Phindile Mposwa, Sibongiseni Tsitsa | D19: Creating and Migrating Chatbots with Conga | E19: Creating and Migrating Chatbots with C | F19: 2021 | G19: 2021 IEEE/ACM 43rd International Conference on Software Engineering: Companion Proceedings (ICSE-Companion) | H19: https://doi.org/10.1109/ICSE-Companion52605.2021.00030 | I19: Chatbots are agents that enable the interaction of channels.Choosinganinadequatetoolmayleadtoincreased users and software by means of written or spoken natural effort [4], lower chatbot quality or project failure. languageconversation.Theiruseisgrowing,andmanycompanies • Challenge 2: How to design chatbots independently of the arestartingtooffertheirservicesviachatbots,e.g.,forbooking, particulartooltoenableearlyreasoningandanalysis,prior shopping or customer support. For this reason, many chatbot to the implementation? Chatbot development tools are very developmenttoolshaveemerged,whichmakeschoosingthemost appropriatetooldifficult.Moreover,thereishardlyanysupport diverse, ranging from low-level programming frameworks for migrating chatbots between tools. (like Rasa) to lowcode development platforms based on To alleviate these issues, we propose a model-driven engi- forms(likeDialogflow).Graspingthedesignbehindachat- neering solution that includes: (i) a domain-specific language bot implementation may be challenging due to accidental, to model chatbots independently of the development tool; (ii) a recommender that suggests the most suitable development technical details of the tools themselves. tool for the given chatbot requirements and model; (iii) code • Challenge 3: How to keep up with the rapidly evolving generatorsthatsynthesizethechatbotcodefortheselectedtool; ecosystem of chatbot tools? With a few exceptions [5], and(iv)parserstoextractchatbotmodelsoutofexistingchatbot most chatbot tools are closed, proprietary software with no implementations.OursolutionissupportedbyawebIDEcalled supportformigrationbetweentools,e.g.,tobenefitfromthe CONGAthatcanbeusedforbothchatbotcreationandmigration. A demo video is available at https://youtu.be/3sw1FDdZ7XY. pricing plans of a competitor. This leads to vendor lock-in. | J19: Phindile Mposwa | K19: Include | L19: Sibongiseni Tsitsa | M19: Include | N19: Include | O19: Included: addresses software/systems modelling; generates or transforms models
A20: 19 | B20: IEEE Xplore | C20: Phindile Mposwa, Sibongiseni Tsitsa | D20: Cross-Domain Deep Code Search with Meta Learning | E20: YitianChai,HongyuZhang,BeijunShen,XiaodongGu | F20: 2022 | G20: 2022 IEEE/ACM 44th International Conference on Software Engineering (ICSE) | H20: https://doi.org/10.1145/3510003.3510125 | I20: 1 INTRODUCTION Recently,pre-trainedprogramminglanguagemodelssuchasCode- Recently,deepneuralnetworks(DNN)havebeenwidelyutilizedfor BERThavedemonstratedsubstantialgainsincodesearch.Despite codesearch[4,9,13,14,28,38].Unliketraditionalkeywordmatch- theirsuccess,theyrelyontheavailabilityoflargeamountsofpar- ingmethods[2,7,16,17,21,22],deepcodesearchmodelsemploy alleldatatofine-tunethesemanticmappingsbetweenqueriesand deepneuralnetworkstolearntherepresentationsofbothqueries code.Thisrestrictstheirpracticalityindomain-specificlanguages andcode,andmeasuretheirsimilaritiesthroughvectordistances. withrelativelyscarceandexpensivedata.Inthispaper,wepropose TheapplicationofDNNssignificantlyimprovestheunderstanding CDCS,anovelapproachfordomain-specificcodesearch.CDCS ofcodesemantics,therebyachievingsuperbperformanceincode employsatransferlearningframeworkwhereaninitialprogram searchtasks[9,13,18,40]. representationmodelispre-trainedonalargecorpusofcommon Amajorchallengefordeepcodesearchistheadaptationofdeep programminglanguages(suchasJavaandPython),andisfurther learningmodelstodomain-specificlanguages.State-of-the-artcode adaptedtodomain-specificlanguagessuchasSolidityandSQL.Un- searchmethodsaremainlydesignedforcommonlanguagessuch likecross-languageCodeBERT,whichisdirectlyfine-tunedinthe asJavaandPython.Theyrelyheavilyontheavailabilityoflarge targetlanguage,CDCSadaptsafew-shotmeta-learningalgorithm paralleldatatolearnthesemanticmappingsbetweencodeand calledMAMLtolearnthegoodinitializationofmodelparameters, naturallanguage[11].Ontheotherhand,thereisanemerging whichcanbebestreusedinadomain-specificlanguage.Weevaluate trendofdomain-specificlanguagessuchasSolidityforsmartcon- theproposedapproachontwodomain-specificlanguages,namely tracts[37,39,44]wherecodesearchisalsoneeded.Thereisoften SolidityandSQL,withmodeltransferredfromtwowidelyused insufficienttrainingdatainspecificdomains,causingpoorfitof languages(PythonandJava).ExperimentalresultsshowthatCDCS deeplearningmodels.Furthermore | J20: Phindile Mposwa | K20: Exclude | L20: Sibongiseni Tsitsa | M20: Exclude | N20: Exclude | O20: Excluded: Generates code directly without using or producing a software model; does not address model generation, transformation, or validation
A21: 20 | B21: IEEE Xplore | C21: Phindile Mposwa, Sibongiseni Tsitsa | D21: Data Analytics and Machine Learning Methods Techniques and Tool for Model-Driven Engineering of Smart IoT Services | E21: Data Analytics and Machine Learning Methods, | F21: 2021 | G21: 2021 IEEE/ACM 43rd International Conference on Software Engineering: Companion Proceedings (ICSE-Companion) | H21: https://doi.org/10.1109/ICSE-Companion52605.2021.00130 | I21: Thisdoctoraldissertationproposesanovelapproach their live-dimension (i.e., re-configuration, re-deployment, to enhance the development of smart services for the Internet live-update, live-enhancement and live-extension), and their of Things (IoT) and smart Cyber-Physical Systems (CPS). The self-dimension, referred to as Self-* capabilities (i.e., self- proposed approach offers abstraction and automation to the documenting, self-monitoring/diagnosis, self-optimizing, self- software engineering processes, as well as the Data Analytics (DA) and Machine Learning (ML) practices. This is realized healingandself-adapting/training)[3].Inaddition,theInternet in an integrated and seamless manner. We implement and is continuously expanding into a pervasive, global and col- validate the proposed approach by extending an open source laborative network of almost every entity/actor (i.e., object or modeling tool, called ThingML. ThingML is a domain-specific thing)surroundingus,includingahugenumberofsensorsand languageandmodelingtoolwithcodegenerationfortheIoT/CPS actuators in our smart environments, thus incorporating and domain.NeitherThingMLnoranyotherIoT/CPSmodelingtool supportsDA/MLatthemodelinglevel.Therefore,astheprimary integrating them into the IoT. Computing devices networked contribution of the doctoral dissertation, we add the necessary into the IoT are even much more heterogeneous, e.g., their syntaxandsemanticsconcerningDA/MLmethodsandtechniques power supplies/storages, processors, main memories and data tothemodelinglanguageofThingML.Moreover,wesupportthe storage capacities can have a very broad spectrum. Thus, APIsofseveralMLlibrariesandframeworksfortheautomated unprecedented challenges are faced by the designers and generation of the source code of the target software in Python andJava.Ourapproachenablesplatform-independent,aswellas developers of such systems [4]. platform-specificmodels.Further,weassistincarryingoutsemi- Prior research [3], [5] has proven that Mod | J21: Phindile Mposwa | K21: Include | L21: Sibongiseni Tsitsa | M21: Include | N21: Include | O21: Included: applies AI within model-driven engineering context
A22: 21 | B22: IEEE Xplore | C22: Phindile Mposwa, Sibongiseni Tsitsa | D22: Decomposing Semantic Loss in Model Transformations with Neural Embeddings | F22: 2026 | H22: https://doi.org/10.1109/ICECET65726.2026.11632676 | I22: Model transformations between heterogeneous Existing techniques can detect semantic loss [2], [3]— metamodels inevitably lose semantic information, yet practi- for instance, through bisimulation or behavioral analysis—but tioners lack tools to diagnose why losses occur: is the tar- they stop at a binary verdict: either preservation holds, or get metamodel inherently unable to express certain source it does not. A practitioner who discovers that a significant constructs, or does the transformation implementation fail to exploit available equivalences? We address this diagnostic gap fraction of source semantics is lost after migration cannot byextendingthemegamodel—thearchitecturalmodelcapturing distinguish between two fundamentally different situations: metamodelrelationships—withquantitativeexpressivitymetrics. We formalize two orthogonal loss components: the Metamodel 1) Inherent metamodel limitation. The target lan- Expressivity Gap (MEG) and the Transformation Coverage Ratio guage cannot express certain source constructs. Java’s (TCR), and prove they decompose total semantic loss exactly. synchronizedblockshavenostructuralequivalentin To make MEG computable without manual expert analysis, Python’sAST.Noamountoftransformationengineering we propose encoding metamodel concepts as vectors via neural will recover this loss; the practitioner must design ex- sentencetransformersandcomputingcross-metamodelsimilarity automatically. A proof-of-concept evaluation on Java-to-Python plicit compensation mechanisms (e.g., wrapping critical AST metamodels demonstrates the feasibility of the approach. sections with threading.Lock). | J22: Phindile Mposwa | K22: Include | L22: Sibongiseni Tsitsa | M22: Include | N22: Include | O22: Included: applies AI to model transformation; addresses metamodel engineering with AI
A23: 22 | B23: IEEE Xplore | C23: Phindile Mposwa, Sibongiseni Tsitsa | D23: Diagram-Aware Automatic Review of Software Design Documents Using Multimodal Large Language Models | E23: Kawasaki, Japan Kawasaki, Japan | F23: 2026 | G23: 2026 IEEE International Conference on Software Analysis, Evolution and Reengineering (SANER) | H23: https://doi.org/10.1109/SANER67736.2026.00108 | I23: With the growing capabilities of Large Language Models (LLMs), their application to software engineering tasks has garnered increasing attention. While our previous work focusedonautomatedreviewofsoftwaredesigndocumentscom- posedoftextandtables,diagram-basedartifactssuchasUMLor screentransitiondiagramsremainedoutsidethescopeofanalysis. Reviewing such documents requires accurate interpretation of structural and semantic elements, including nodes, edges, and transition conditions. Thispaperproposesahybriddiagram-understandingmethod thatleveragesmultimodalLLMstogetherwithdiagramstructure extracted from Office Open XML (OOXML) representations, guided by Chain-of-Thought prompting, to incrementally in- Fig.1. IllustrationofMultimodalLLMUtilizationintheReviewProcess terpret diagrams in real-world design documents. The method enables integrated analysis across diagrams, tables, and textual content within the review process. Evaluation results show that graph-structured UML-style diagrams, including screen tran- theproposedapproachachieveshighaccuracyintasksinvolving sition diagrams and business process flows. These diagrams structural recognition, such as consistency checking. However, encode functional behavior, UI flow, and system structure in the results also highlight persistent challenges in semantic-level review tasks, particularly in interpreting complex transition graph-based formats, and thus must be interpreted accurately conditions. These findings provide insights into the current to support comprehensive review. capabilitiesandlimitationsofmultimodalLLMsforhigh-stakes While recent multimodal LLMs such as GPT-4V and GPT- design document reviews. 4o support image input, our initial experiments indicated IndexTerms—SoftwareDesignReview,LargeLanguageMod- thatrawimage-baseddiagramcomprehensionisofteninsuffi- els, Diagram Understanding cient for high-stakes review tasks. Complex diagrams require precise recognition of node labels, edge relationships, and | J23: Phindile Mposwa | K23: Include | L23: Sibongiseni Tsitsa | M23: Include | N23: Include | O23: Included: applies AI to model transformation; applies AI to UML/software model artefacts
A24: 23 | B24: IEEE Xplore | C24: Phindile Mposwa, Sibongiseni Tsitsa | D24: Digital Forensics Domain and Metamodeling Development Approaches | E24: College of Computer Science and College of Computer Science and College of Computer Science and | F24: 2021 | H24: https://doi.org/10.1109/ICSCEE50312.2021.9497935 | I24: Metamodeling is used as a general technique for [14]. Therefore, semantic metamodeling language (high integrating and defining models from different domains. This abstract model) is required to organize, unify, and structure the technique can be used in diverse application domains, especially DFs domain knowledge in one standardized model. For this for purposes of standardization. Also, this process mainly has a purpose, the metamodeling approach is a proper method to focus on the identification of general concepts that exist in develop a sematic metamodeling language (metamodel) for the various problem domain and their relations and to solve DFs domain. Metamodeling is used as a general technique for complexity, interoperability, and heterogeneity aspects of integrating and defining models from different domains [15]. different domains. Several diverse metamodeling development Common concepts of these different views can be identified approaches have been proposed in the literature to develop and shared. The metamodeling technique consequently can be metamodels. Each metamodeling development process has some applied in quite different application domains, especially for advantages and disadvantages too. Therefore, the objective of standardization purposes. Metamodeling is simply the this paper is to provide a comprehensive review of existing identification of general concepts that exist in each problem metamodeling development approaches and conduct a domain and their relations. It is used to solve the complexity, comparative study among them-eventually selecting the best interoperability, and heterogeneity of the domain [16]. approach for metamodel development in the perspective of digital forensics. Metamodels should therefore be rigorously defined as well as being well-structured. The metamodel is a model about a | J24: Phindile Mposwa | K24: Include | L24: Sibongiseni Tsitsa | M24: Include | N24: Include | O24: Included: addresses software/systems modelling
A25: 24 | B25: IEEE Xplore | C25: Phindile Mposwa, Sibongiseni Tsitsa | D25: Enhancing Model-Driven Reverse Engineering Using Machine Learning | F25: 2024 | G25: 2024 IEEE/ACM 46th International Conference on Software Engineering: Companion Proceedings (ICSE-Companion) | H25: https://doi.org/10.1145/3639478.3639797 | I25: differentlevelscanbeautomaticallytransformedintoeachother. Organizationsoftenrelyonlargeapplicationsthatareclassifiedas Reverseengineeringtechniquesforsoftwaresystemshavebeenex- legacysystemsduetotheirdependenceonoutdatedprogramming tensivelystudiedoverthepast20years,andnumerousapproaches, languagesorplatforms.Tomodernizethesesystems,itisnecessary includingthemodel-drivenapproach(MDRE)—-thesubjectofour tounderstandtheirarchitecture,functionality,andbusinessrules. study—-havebeenintroduced.Raibuletetal.[19]presentedacom- Ourresearchaimstodefineanovelmodel-drivenreverseengineer- prehensiveanalysisofMDREapproachesintheliterature,upto ing(MDRE)approachtoextractUnifiedModelingLanguage(UML) 2017.Throughasystematicliteraturereview(SLR),theauthors andObjectConstraintLanguage(OCL)representationsfromsource highlight15MDREapproachesanddiscusstheirvariousfeatures codeusingLargeLanguageModels(LLMs). andobjectives.WealsoconductedanSLRof938relevantpublica- tionsinthisdomainfrom2000to2023togainacomprehensive understandingofcurrentresearchinMDREapproaches.Wefound | J25: Phindile Mposwa | K25: Include | L25: Sibongiseni Tsitsa | M25: Include | N25: Include | O25: Included: applies AI to reverse engineering/code-to-model extraction; applies AI to UML/software model artefacts; applies AI within model-driven engineering context
