Workbook

Sheet TOC & Overview
A2: CPUT PROJECTS 4: LIT-TRACKER SYSTEM
A3: Research Title: The Adoption of Cloud Computing by Small to Medium Enterprises in South Africa
A4: Student: Thabiso Patrick Matsaba (Student No: 220296006) | Supervisor: Dr Kenneth Ohei
A5: 5 October 2026 | v3.0 | 40 included studies, verified against PDFs | Standardized for Advanced Diploma ICT Projects 4
A7: WORKBOOK SECTIONS
A8: Sheet Name | B8: Description | C8: Primary Academic Purpose | D8: Navigation Link
A9: TOC & Overview | B9: Current sheet containing navigation, formatting guidelines, and project metadata. | C9: Project Organization & Setup | D9: =HYPERLINK("#'TOC & Overview'!A1", "Go to sheet →") -> Go to sheet →
A10: PRISMA Search Log | B10: Logs and quantifies literature search outcomes across 8 databases (Scopus, Web of Science, Google Scholar, etc.). | C10: Systematic Literature Review Rigor (SO5) | D10: =HYPERLINK("#'PRISMA Search Log'!A1", "Go to sheet →") -> Go to sheet →
A11: Article Screening & MMAT | B11: Tracks study selection, inclusion/exclusion decisions, and applies the Mixed Methods Appraisal Tool. | C11: Methodological Quality Appraisal (SO2, SO5) | D11: =HYPERLINK("#'Article Screening & MMAT'!A1", "Go to sheet →") -> Go to sheet →
A12: Data Extraction Matrix | B12: Extracts specific findings, paragraph quotes, rationale, local paths, and maps them to TOE dimensions. | C12: Synthesis of Existing Literature (SO6, SO7) | D12: =HYPERLINK("#'Data Extraction Matrix'!A1", "Go to sheet →") -> Go to sheet →
A15: SPREADSHEET COLOR & DESIGN CONVENTIONS
A16: Visual Style / Color | B16: Assigned Meaning | C16: Applicable Cells | D16: Action/Audience Instruction
A17: Header Row (Dark Blue) | B17: Table column definitions and structural headers. | C17: Top row of data tables | D17: Do not modify. Standardized system headers.
A18: Section Header (Medium Blue) | B18: Groups sub-sections or categories within sheets. | C18: Merged rows separating sections | D18: Do not modify. Structural markers.
A19: Input Cell (Light Blue) | B19: Assumptions, manual entries, or researcher data logging. | C19: Columns requiring data entry | D19: Enter search details, decisions, or text extracts.
A20: Calculated Cell (Light Green) | B20: Formulas (SUM, COUNTIF, mathematical subtractions). | C20: Scores, totals, automatically mapped values | D20: Do not modify. Locked/formula-driven cell.
A21: Zebra Row (Light Gray) | B21: Zebra striping on alternating rows for readability. | C21: Alternating data rows | D21: Aids visual tracking across large datasets.
A22: Placeholder Cell (Light Yellow) | B22: Simulated/sample data for guidelines and training. | C22: Italicized research template examples | D22: Replace with actual collected data during study.

Sheet PRISMA Search Log
A1: PRISMA SEARCH LOG
A2: This log maps and quantifies search outcomes across the 8 required databases. Use the exact Boolean query to replicate search results.
A4: Database Name | B4: Search Date | C4: Search Query / Boolean String | D4: Search Filters Applied | E4: Initial Records Retrieved | F4: Duplicates Removed | G4: Records Screened | H4: Records Excluded after Title/Abstract | I4: Full-Text Articles Assessed | J4: Full-Text Articles Excluded with Reasons | K4: Total Included in Review
A5: Scopus | B5: 2026-08-15 | C5: ("cloud computing adoption" OR "cloud adoption") AND ("SMEs" OR "small and medium enterprises" OR "SMMEs") AND ("Technology Organisation Environment" OR "TOE framework") AND ("South Africa" OR "developing economy") | D5: 2020-2026, English, Peer-Reviewed | E5: 45 | F5: 10 | G5: =E5-F5 -> 35 | H5: 20 | I5: =G5-H5 -> 15 | J5: 8 | K5: =I5-J5 -> 7
A6: Web of Science | B6: 2026-08-15 | C6: ("cloud computing adoption" OR "cloud adoption") AND ("SMEs" OR "small and medium enterprises") AND ("TOE framework" OR "Technology-Organisation-Environment") AND ("South Africa" OR "developing economy") | D6: 2020-2026, English, Peer-Reviewed | E6: 22 | F6: 8 | G6: =E6-F6 -> 14 | H6: 8 | I6: =G6-H6 -> 6 | J6: 4 | K6: =I6-J6 -> 2
A7: IEEE Xplore | B7: 2026-08-15 | C7: ("cloud adoption") AND ("SME" OR "small enterprise") AND ("TOE") AND ("South Africa") | D7: 2020-2026, English, Peer-Reviewed | E7: 18 | F7: 5 | G7: =E7-F7 -> 13 | H7: 7 | I7: =G7-H7 -> 6 | J7: 3 | K7: =I7-J7 -> 3
A8: ACM Digital Library | B8: 2026-08-15 | C8: ("cloud computing adoption") AND ("SMEs") AND ("TOE") AND ("developing economy") | D8: 2020-2026, English, Peer-Reviewed | E8: 12 | F8: 2 | G8: =E8-F8 -> 10 | H8: 6 | I8: =G8-H8 -> 4 | J8: 2 | K8: =I8-J8 -> 2
A9: ScienceDirect | B9: 2026-08-15 | C9: ("cloud adoption") AND ("SMEs") AND ("TOE framework") AND ("developing economy") | D9: 2020-2026, English, Peer-Reviewed | E9: 38 | F9: 15 | G9: =E9-F9 -> 23 | H9: 12 | I9: =G9-H9 -> 11 | J9: 6 | K9: =I9-J9 -> 5
A10: SpringerLink | B10: 2026-08-15 | C10: ("cloud computing adoption") AND ("SMEs") AND ("Technology Organisation Environment") AND ("South Africa") | D10: 2020-2026, English, Peer-Reviewed | E10: 25 | F10: 12 | G10: =E10-F10 -> 13 | H10: 8 | I10: =G10-H10 -> 5 | J10: 3 | K10: =I10-J10 -> 2
A11: Google Scholar | B11: 2026-08-15 | C11: ("cloud computing adoption" OR "cloud adoption") AND ("SMEs" OR "small and medium enterprises") AND ("TOE" OR "Technology-Organisation-Environment") AND ("South Africa" OR "developing economy") | D11: 2020-2026, English, Peer-Reviewed | E11: 150 | F11: 45 | G11: =E11-F11 -> 105 | H11: 85 | I11: =G11-H11 -> 20 | J11: 15 | K11: =I11-J11 -> 5
A12: MDPI | B12: 2026-08-15 | C12: ("cloud adoption" OR "cloud computing adoption") AND ("SMEs" OR "small business") AND ("TOE framework") AND ("South Africa" OR "developing economy") | D12: 2020-2026, English, Peer-Reviewed | E12: 32 | F12: 5 | G12: =E12-F12 -> 27 | H12: 18 | I12: =G12-H12 -> 9 | J12: 5 | K12: =I12-J12 -> 4
A13: Supplementary search (Google Scholar and publisher sites) | B13: 2026-10-05 | C13: Same core terms: cloud computing adoption AND SMEs AND (TOE OR "Technology Organisation Environment"); candidate titles followed to publisher pages | D13: 2020-2026, English, Peer-Reviewed | E13: 39 | F13: 0 | G13: =E13-F13 -> 39 | H13: 11 | I13: =G13-H13 -> 28 | J13: 7 | K13: =I13-J13 -> 21
A14: TOTALS | B14: - | C14: - | D14: - | E14: =SUM(E5:E13) -> 381 | F14: =SUM(F5:F13) -> 102 | G14: =SUM(G5:G13) -> 279 | H14: =SUM(H5:H13) -> 175 | I14: =SUM(I5:I13) -> 104 | J14: =SUM(J5:J13) -> 53 | K14: =SUM(K5:K13) -> 51
A16: RECONCILIATION TO THE FINAL INCLUDED SET
A17: Eligible after full-text assessment, original search (rows 5-12) | B17: =SUM(K5:K12) -> 30
A18: Removed at verification: no PDF retained, wrong file retrieved, or placeholder row | B18: =B17-B19 -> 11
A19: Included from original search, verified against PDF (ART-001 to ART-019) | B19: 19
A20: Included from supplementary search (ART-020 to ART-040) | B20: =K13 -> 21
A21: TOTAL STUDIES INCLUDED | B21: =B19+B20 -> 40
A22: Check: rows marked Included on the screening sheet | B22: =COUNTIF('Article Screening & MMAT'!E5:E44,"Included") -> 40
A23: Supplementary search: 39 candidate records identified; 11 not retrieved (paywall or no access); 28 full texts assessed; 7 excluded (3 published before 2020, 2 not peer-reviewed, 2 did not use TOE).
A24: NOTE: 4 included studies are pre-2020 (ART-003, 015, 016, 017) and were kept as foundational studies. The original-search counts in rows 5-12 are as logged on 15 Aug 2026 and were not re-verified.

Sheet Article Screening & MMAT
A1: ARTICLE SCREENING & QUALITY APPRAISAL (MMAT)
A2: Screening decisions and MMAT appraisal for the 40 included studies. Every row was checked against the PDF in /Articles on 5 Oct 2026. MMAT scores for ART-020 to ART-040 are provisional (based on abstract and method) and must be confirmed by the researcher.
A4: Article ID | B4: Author(s) & Year | C4: Article Title | D4: Source Database | E4: Inclusion Decision | F4: Exclusion Reason | G4: MMAT Q1: Clear RQ? | H4: MMAT Q2: Proper Design? | I4: MMAT Q3: Rigorous Data? | J4: MMAT Q4: Robust Analysis? | K4: MMAT Q5: Substantiated? | L4: MMAT Yes Count | M4: Quality Rating | N4: Year | O4: Country / Context | P4: Research Method | Q4: Publication Channel | R4: PDF File Name | S4: Former ID | T4: Verification Note
A5: ART-001 | B5: Aligarh, Sutopo & Widarjo, 2023 | C5: The antecedents of cloud computing adoption and its consequences for MSMEs' performance: A model based on the TOE framework | D5: Google Scholar | E5: Included | F5: N/A - Included | G5: Yes | H5: Yes | I5: Yes | J5: Yes | K5: Yes | L5: =COUNTIF(G5:K5,"Yes") -> 5 | M5: =IF(L5>=4,"High",IF(L5=3,"Moderate","Low")) -> High | N5: 2023 | O5: Indonesia | P5: Quantitative survey (197 MSMEs; SEM-PLS) | Q5: Journal | R5: ART-001_Aligarh_2023.pdf | S5: ART-001 | T5: Author corrected from "Santos et al." to match the PDF.
A6: ART-002 | B6: Abu Bakar et al., 2024 | C6: Adoption of Industry 4.0 with cloud computing as a mediator: Evaluation using TOE framework for SMEs | D6: Open-access journal site | E6: Included | F6: N/A - Included | G6: Yes | H6: Yes | I6: Yes | J6: Yes | K6: Yes | L6: =COUNTIF(G6:K6,"Yes") -> 5 | M6: =IF(L6>=4,"High",IF(L6=3,"Moderate","Low")) -> High | N6: 2024 | O6: Malaysia | P6: Quantitative pilot survey (PLS-SEM) | Q6: Journal | R6: ART-002_AbuBakar_2024.pdf | S6: ART-002 | T6: Source corrected: JOIV is not an MDPI journal.
A7: ART-003 | B7: Al-Dwairi, Al-Tweit & Zyout, 2018 | C7: Factors influencing cloud-computing adoption in small and medium e-commerce enterprises in Jordan | D7: ACM Digital Library | E7: Included | F7: N/A - Included | G7: Yes | H7: Yes | I7: Yes | J7: No | K7: Yes | L7: =COUNTIF(G7:K7,"Yes") -> 4 | M7: =IF(L7>=4,"High",IF(L7=3,"Moderate","Low")) -> High | N7: 2018 | O7: Jordan | P7: Qualitative interviews (16 managers) | Q7: Conference | R7: ART-003_AlDwairi_2018.pdf | S7: ART-003 | T7: PRE-2020. Author/year corrected from "Yaseen et al., 2023" to match the PDF (ICIEB 2018).
A8: ART-004 | B8: Mokwena & Fatoki, 2024 | C8: Barriers of cloud computing adoption by small and medium enterprises in Polokwane Municipality | D8: Google Scholar | E8: Included | F8: N/A - Included | G8: Yes | H8: Yes | I8: Yes | J8: Yes | K8: Yes | L8: =COUNTIF(G8:K8,"Yes") -> 5 | M8: =IF(L8>=4,"High",IF(L8=3,"Moderate","Low")) -> High | N8: 2024 | O8: South Africa | P8: Quantitative survey (106 of 230 SMEs) | Q8: Journal | R8: ART-004_Mokwena_2024.pdf | S8: ART-004 | T8: Author corrected from "Mokwena & Sithole".
A9: ART-005 | B9: Mkhize et al., 2025 | C9: Evaluating the impact of cloud computing on SME performance: A systematic review | D9: MDPI | E9: Included | F9: N/A - Included | G9: Yes | H9: Yes | I9: Yes | J9: Yes | K9: Yes | L9: =COUNTIF(G9:K9,"Yes") -> 5 | M9: =IF(L9>=4,"High",IF(L9=3,"Moderate","Low")) -> High | N9: 2025 | O9: Global review | P9: Systematic review (PRISMA 2020; 90 studies) | Q9: Journal | R9: ART-005_Mkhize_2025.pdf | S9: ART-005
A10: ART-006 | B10: Sithole & Ruhode, 2021 | C10: Cloud computing adoption: Opportunities and challenges for small, medium and micro enterprises in South Africa | D10: Google Scholar | E10: Included | F10: N/A - Included | G10: Yes | H10: Yes | I10: Yes | J10: Yes | K10: Yes | L10: =COUNTIF(G10:K10,"Yes") -> 5 | M10: =IF(L10>=4,"High",IF(L10=3,"Moderate","Low")) -> High | N10: 2021 | O10: South Africa | P10: Quantitative online survey | Q10: Conference | R10: ART-006_Sithole_2021.pdf | S10: ART-008 | T10: POPIA is not mentioned in the PDF (earlier tracker said Yes).
A11: ART-007 | B11: Mhlongo et al., 2024 | C11: Reviewing the impact of cloud computing on small and medium enterprises in Africa | D11: Google Scholar | E11: Included | F11: N/A - Included | G11: Yes | H11: Yes | I11: Yes | J11: Yes | K11: Yes | L11: =COUNTIF(G11:K11,"Yes") -> 5 | M11: =IF(L11>=4,"High",IF(L11=3,"Moderate","Low")) -> High | N11: 2024 | O11: Africa | P11: Narrative review | Q11: Journal | R11: ART-007_Mhlongo_2024.pdf | S11: ART-009
A12: ART-008 | B12: Ilahi et al., 2024 | C12: Small and medium enterprises (SMEs): Key factors affecting the adoption of cloud computing | D12: Open-access journal site | E12: Included | F12: N/A - Included | G12: Yes | H12: Yes | I12: Yes | J12: Yes | K12: Yes | L12: =COUNTIF(G12:K12,"Yes") -> 5 | M12: =IF(L12>=4,"High",IF(L12=3,"Moderate","Low")) -> High | N12: 2024 | O12: Global review | P12: Literature review of TOE studies | Q12: Journal | R12: ART-008_Ilahi_2024.pdf | S12: ART-010 | T12: Source corrected: not a ScienceDirect journal.
A13: ART-009 | B13: Ahmad, Mahomed & Hashim, 2025 | C13: Cloud computing adoption in SMEs: Exploring IaaS, PaaS and SaaS through a bibliometric study | D13: Scopus | E13: Included | F13: N/A - Included | G13: Yes | H13: Yes | I13: Yes | J13: Yes | K13: Yes | L13: =COUNTIF(G13:K13,"Yes") -> 5 | M13: =IF(L13>=4,"High",IF(L13=3,"Moderate","Low")) -> High | N13: 2025 | O13: Global review | P13: Bibliometric analysis (662 articles) | Q13: Journal | R13: ART-009_Ahmad_2025.pdf | S13: ART-011
A14: ART-010 | B14: Jayeola et al., 2022 | C14: Cloud computing adoption in small and medium enterprises (SMEs): A systematic literature review and directions for future research | D14: Scopus | E14: Included | F14: N/A - Included | G14: Yes | H14: Yes | I14: Yes | J14: Yes | K14: Yes | L14: =COUNTIF(G14:K14,"Yes") -> 5 | M14: =IF(L14>=4,"High",IF(L14=3,"Moderate","Low")) -> High | N14: 2022 | O14: Global review | P14: Systematic review (76 articles) | Q14: Journal | R14: ART-010_Jayeola_2022.pdf | S14: ART-012
A15: ART-011 | B15: Khayer, Jahan, Hossain & Hossain, 2020 | C15: The adoption of cloud computing in small and medium enterprises: A developing country perspective | D15: Scopus | E15: Included | F15: N/A - Included | G15: Yes | H15: Yes | I15: Yes | J15: Yes | K15: Yes | L15: =COUNTIF(G15:K15,"Yes") -> 5 | M15: =IF(L15>=4,"High",IF(L15=3,"Moderate","Low")) -> High | N15: 2020 | O15: Bangladesh | P15: Quantitative survey (372 SMEs; SEM) | Q15: Journal | R15: ART-011_Khayer_2020a.pdf | S15: ART-013 | T15: Published online 2020; issue 51(1) dated 2021.
A16: ART-012 | B16: Skafi, Yunis & Zekri, 2020 | C16: Factors influencing SMEs' adoption of cloud computing services in Lebanon: An empirical analysis using TOE and contextual theory | D16: IEEE Xplore | E16: Included | F16: N/A - Included | G16: Yes | H16: Yes | I16: Yes | J16: Yes | K16: Yes | L16: =COUNTIF(G16:K16,"Yes") -> 5 | M16: =IF(L16>=4,"High",IF(L16=3,"Moderate","Low")) -> High | N16: 2020 | O16: Lebanon | P16: Quantitative survey (139 respondents) | Q16: Journal | R16: ART-012_Skafi_2020.pdf | S16: ART-014
A17: ART-013 | B17: Shetty & Panda, 2021 | C17: An overview of cloud computing in SMEs | D17: Google Scholar | E17: Included | F17: N/A - Included | G17: Yes | H17: Yes | I17: Yes | J17: Yes | K17: Yes | L17: =COUNTIF(G17:K17,"Yes") -> 5 | M17: =IF(L17>=4,"High",IF(L17=3,"Moderate","Low")) -> High | N17: 2021 | O17: Global review | P17: Systematic and narrative review (92 articles) | Q17: Journal | R17: ART-013_Shetty_2021.pdf | S17: ART-015
A18: ART-014 | B18: Picoto, Crespo & Carvalho, 2021 | C18: The influence of the technology-organization-environment framework and strategic orientation on cloud computing use, enterprise mobility, and performance | D18: SciELO | E18: Included | F18: N/A - Included | G18: Yes | H18: Yes | I18: Yes | J18: Yes | K18: Yes | L18: =COUNTIF(G18:K18,"Yes") -> 5 | M18: =IF(L18>=4,"High",IF(L18=3,"Moderate","Low")) -> High | N18: 2021 | O18: Portugal | P18: Quantitative survey (137 organisations; PLS-SEM) | Q18: Journal | R18: ART-014_Picoto_2021.pdf | S18: ART-016 | T18: BORDERLINE: Portugal is a high-income country and the sample is organisations, not only SMEs. Correct PDF now in folder.
A19: ART-015 | B19: Salleh, Hussin & Suhaimi, 2018 | C19: A systematic literature review of cloud computing adoption and impacts among small medium enterprises (SMEs) | D19: IEEE Xplore | E19: Included | F19: N/A - Included | G19: Yes | H19: Yes | I19: Yes | J19: Yes | K19: Yes | L19: =COUNTIF(G19:K19,"Yes") -> 5 | M19: =IF(L19>=4,"High",IF(L19=3,"Moderate","Low")) -> High | N19: 2018 | O19: Global review | P19: Systematic review (39 articles) | Q19: Conference | R19: ART-015_Salleh_2018.pdf | S19: ART-017 | T19: PRE-2020.
A20: ART-016 | B20: Nuskiya, 2017 | C20: Factors influencing cloud computing adoption by SMEs in eastern region of Sri Lanka | D20: Google Scholar | E20: Included | F20: N/A - Included | G20: Yes | H20: Yes | I20: Yes | J20: Yes | K20: Yes | L20: =COUNTIF(G20:K20,"Yes") -> 5 | M20: =IF(L20>=4,"High",IF(L20=3,"Moderate","Low")) -> High | N20: 2017 | O20: Sri Lanka | P20: Questionnaire and discussion (50 enterprises) | Q20: Journal | R20: ART-016_Nuskiya_2017.pdf | S20: ART-018 | T20: PRE-2020.
A21: ART-017 | B21: Abubakar, Bass & Allison, 2014 | C21: Cloud computing: Adoption issues for sub-Saharan African SMEs | D21: Wiley Online Library | E21: Included | F21: N/A - Included | G21: Yes | H21: Yes | I21: Yes | J21: Yes | K21: Yes | L21: =COUNTIF(G21:K21,"Yes") -> 5 | M21: =IF(L21>=4,"High",IF(L21=3,"Moderate","Low")) -> High | N21: 2014 | O21: Nigeria | P21: Qualitative interviews (10 SMEs) | Q21: Journal | R21: ART-017_Abubakar_2014.pdf | S21: ART-019 | T21: PRE-2020. Electricity discussed.
A22: ART-018 | B22: Modisane & Jokonya, 2021 | C22: Evaluating the benefits of cloud computing in small, medium and micro-sized enterprises (SMMEs) | D22: ScienceDirect | E22: Included | F22: N/A - Included | G22: Yes | H22: Yes | I22: Yes | J22: Yes | K22: Yes | L22: =COUNTIF(G22:K22,"Yes") -> 5 | M22: =IF(L22>=4,"High",IF(L22=3,"Moderate","Low")) -> High | N22: 2021 | O22: South Africa | P22: Quantitative survey (TOE constructs) | Q22: Conference | R22: ART-018_Modisane_2021.pdf | S22: ART-021 | T22: POPIA and electricity are not mentioned in the PDF (earlier tracker said Yes).
A23: ART-019 | B23: Mohlameane & Ruxwana, 2020 | C23: Exploring the impact of cloud computing on existing South African regulatory frameworks | D23: Google Scholar | E23: Included | F23: N/A - Included | G23: Yes | H23: Yes | I23: Yes | J23: Yes | K23: Yes | L23: =COUNTIF(G23:K23,"Yes") -> 5 | M23: =IF(L23>=4,"High",IF(L23=3,"Moderate","Low")) -> High | N23: 2020 | O23: South Africa | P23: Multi-method (interviews, questionnaires, documents; 50 participants) | Q23: Journal | R23: ART-019_Mohlameane_2020.pdf | S23: ART-022 | T23: The only included study that discusses POPIA.
A24: ART-020 | B24: Mudzamba, van der Schyff & Renaud, 2022 | C24: The challenges of cloud adoption among South African small to medium enterprises: A thematic analysis | D24: Wiley Online Library | E24: Included | F24: N/A - Included | G24: Yes | H24: Yes | I24: Yes | J24: Yes | K24: Yes | L24: =COUNTIF(G24:K24,"Yes") -> 5 | M24: =IF(L24>=4,"High",IF(L24=3,"Moderate","Low")) -> High | N24: 2022 | O24: South Africa | P24: Qualitative (13 interviews, 9 SMEs) | Q24: Journal | R24: ART-020_Mudzamba_2022.pdf | S24: new
A25: ART-021 | B25: Morema, Adeyelure & Seaba, 2026 | C25: Cloud ERP adoption in Ekurhuleni's logistics SMEs: A conceptual model | D25: Open-access journal site | E25: Included | F25: N/A - Included | G25: Yes | H25: Yes | I25: Yes | J25: Yes | K25: Yes | L25: =COUNTIF(G25:K25,"Yes") -> 5 | M25: =IF(L25>=4,"High",IF(L25=3,"Moderate","Low")) -> High | N25: 2026 | O25: South Africa | P25: Quantitative survey (TOE-based model; 10 of 11 hypotheses supported) | Q25: Journal | R25: ART-021_Morema_2026.pdf | S25: new | T25: Load shedding is mentioned once. The PDF is a browser print with the right edge cut off: download the proper PDF and re-check the quote.
A26: ART-022 | B26: Buhari, Muhammad, Bodinga & Sifawa, 2022 | C26: Adoption of cloud computing by IT based small and medium scale enterprises in Northwestern Nigeria | D26: ResearchGate | E26: Included | F26: N/A - Included | G26: Yes | H26: Yes | I26: Yes | J26: No | K26: Yes | L26: =COUNTIF(G26:K26,"Yes") -> 4 | M26: =IF(L26>=4,"High",IF(L26=3,"Moderate","Low")) -> High | N26: 2022 | O26: Nigeria | P26: Quantitative survey (109 of 150 responded) | Q26: Journal | R26: ART-022_Buhari_2022.pdf | S26: new | T26: TOE is mentioned only briefly (3 times).
A27: ART-023 | B27: Gui et al., 2020 | C27: Cloud computing adoption using TOE framework for Indonesia's micro small medium enterprises | D27: Open-access journal site | E27: Included | F27: N/A - Included | G27: Yes | H27: Yes | I27: Yes | J27: Yes | K27: Yes | L27: =COUNTIF(G27:K27,"Yes") -> 5 | M27: =IF(L27>=4,"High",IF(L27=3,"Moderate","Low")) -> High | N27: 2020 | O27: Indonesia | P27: Quantitative survey (135 participants; SmartPLS) | Q27: Journal | R27: ART-023_Gui_2020.pdf | S27: new | T27: Year taken from the PDF creation date (Dec 2020); confirm volume/issue on the JOIV site.
A28: ART-024 | B28: Al-Sharafi et al., 2023 | C28: Determinants of cloud computing integration and its impact on sustainable performance in SMEs: An empirical investigation using the SEM-ANN approach | D28: PubMed Central | E28: Included | F28: N/A - Included | G28: Yes | H28: Yes | I28: Yes | J28: Yes | K28: Yes | L28: =COUNTIF(G28:K28,"Yes") -> 5 | M28: =IF(L28>=4,"High",IF(L28=3,"Moderate","Low")) -> High | N28: 2023 | O28: Malaysia | P28: Quantitative survey (415 SMEs; SEM-ANN) | Q28: Journal | R28: ART-024_AlSharafi_2023.pdf | S28: new
A29: ART-025 | B29: Khayer, Talukder, Bao & Hossain, 2020 | C29: Cloud computing adoption and its impact on SMEs' performance for cloud supported operations: A dual-stage analytical approach | D29: ScienceDirect | E29: Included | F29: N/A - Included | G29: Yes | H29: Yes | I29: Yes | J29: Yes | K29: Yes | L29: =COUNTIF(G29:K29,"Yes") -> 5 | M29: =IF(L29>=4,"High",IF(L29=3,"Moderate","Low")) -> High | N29: 2020 | O29: Bangladesh | P29: Quantitative survey (SEM-ANN) | Q29: Journal | R29: ART-025_Khayer_2020b.pdf | S29: new | T29: Server location finding is relevant to data sovereignty.
A30: ART-026 | B30: Alamri & Alzahrani, 2024 | C30: Navigating the clouds: An exploratory research of cloud computing adoption in Saudi Arabia's small and medium enterprises | D30: Open-access journal site | E30: Included | F30: N/A - Included | G30: Yes | H30: Yes | I30: Yes | J30: Yes | K30: Yes | L30: =COUNTIF(G30:K30,"Yes") -> 5 | M30: =IF(L30>=4,"High",IF(L30=3,"Moderate","Low")) -> High | N30: 2024 | O30: Saudi Arabia | P30: Mixed methods | Q30: Journal | R30: ART-026_Alamri_2024.pdf | S30: new | T30: Saudi Arabia is a high-income country.
A31: ART-027 | B31: Mujalli et al., 2024 | C31: Investigating the factors affecting the adoption of cloud accounting in Saudi Arabia's small and medium-sized enterprises (SMEs) | D31: ScienceDirect | E31: Included | F31: N/A - Included | G31: Yes | H31: Yes | I31: Yes | J31: Yes | K31: Yes | L31: =COUNTIF(G31:K31,"Yes") -> 5 | M31: =IF(L31>=4,"High",IF(L31=3,"Moderate","Low")) -> High | N31: 2024 | O31: Saudi Arabia | P31: Quantitative survey (354 responses; PLS-SEM) | Q31: Journal | R31: ART-027_Mujalli_2024.pdf | S31: new | T31: Cloud accounting (SaaS). Saudi Arabia is a high-income country.
A32: ART-028 | B32: Sayginer & Ercan, 2021 | C32: Multi-perspective decision-making cloud computing adoption model for small and medium enterprises (SMEs) | D32: Open-access journal site | E32: Included | F32: N/A - Included | G32: Yes | H32: Yes | I32: Yes | J32: Yes | K32: Yes | L32: =COUNTIF(G32:K32,"Yes") -> 5 | M32: =IF(L32>=4,"High",IF(L32=3,"Moderate","Low")) -> High | N32: 2021 | O32: Turkey | P32: Quantitative survey (140 IT decision-makers) | Q32: Journal | R32: ART-028_Sayginer_2021.pdf | S32: new | T32: Scanned PDF: quote read by OCR, check it by eye.
A33: ART-029 | B33: Nosheen, Omar & Hashim, 2025 | C33: Investigating the determinants of cloud computing-software as a service adoption in Pakistani SMEs from the perspective of SME managers | D33: Open-access journal site | E33: Included | F33: N/A - Included | G33: Yes | H33: Yes | I33: Yes | J33: Yes | K33: Yes | L33: =COUNTIF(G33:K33,"Yes") -> 5 | M33: =IF(L33>=4,"High",IF(L33=3,"Moderate","Low")) -> High | N33: 2025 | O33: Pakistan | P33: Quantitative survey | Q33: Journal | R33: ART-029_Nosheen_2025.pdf | S33: new
A34: ART-030 | B34: Sastararuji et al., 2021 | C34: Cloud accounting adoption in small and medium enterprises: An integrated conceptual framework | D34: ACM Digital Library | E34: Included | F34: N/A - Included | G34: Yes | H34: Yes | I34: Can't tell | J34: Can't tell | K34: Yes | L34: =COUNTIF(G34:K34,"Yes") -> 3 | M34: =IF(L34>=4,"High",IF(L34=3,"Moderate","Low")) -> Moderate | N34: 2021 | O34: Thailand | P34: Conceptual framework (literature and qualitative) | Q34: Conference | R34: ART-030_Sastararuji_2021.pdf | S34: new | T34: Conceptual paper: MMAT criteria 3–4 marked "Can't tell".
A35: ART-031 | B35: Ali, Hassan, Abdullahi & Abdulah, 2023 | C35: Analyzing the factors influencing the adoption of cloud computing by SMEs using the SEM approach | D35: Open-access journal site | E35: Included | F35: N/A - Included | G35: Yes | H35: Yes | I35: Yes | J35: Yes | K35: Yes | L35: =COUNTIF(G35:K35,"Yes") -> 5 | M35: =IF(L35>=4,"High",IF(L35=3,"Moderate","Low")) -> High | N35: 2023 | O35: Somalia | P35: Quantitative survey (195 respondents; SEM) | Q35: Journal | R35: ART-031_Ali_2023.pdf | S35: new | T35: Security and competitive pressure were NOT significant.
A36: ART-032 | B36: Ognjanović, Šendelj, Daković-Tadić & Kožuh, 2024 | C36: A longitudinal study on the adoption of cloud computing in micro, small, and medium enterprises in Montenegro | D36: MDPI | E36: Included | F36: N/A - Included | G36: Yes | H36: Yes | I36: Yes | J36: Yes | K36: Yes | L36: =COUNTIF(G36:K36,"Yes") -> 5 | M36: =IF(L36>=4,"High",IF(L36=3,"Moderate","Low")) -> High | N36: 2024 | O36: Montenegro | P36: Mixed methods, longitudinal (71 MSMEs; 15 interviews) | Q36: Journal | R36: ART-032_Ognjanovic_2024.pdf | S36: new
A37: ART-033 | B37: Adjei, Adams & Mamattah, 2021 | C37: Cloud computing adoption in Ghana; accounting for institutional factors | D37: ScienceDirect | E37: Included | F37: N/A - Included | G37: Yes | H37: Yes | I37: Yes | J37: Yes | K37: Yes | L37: =COUNTIF(G37:K37,"Yes") -> 5 | M37: =IF(L37>=4,"High",IF(L37=3,"Moderate","Low")) -> High | N37: 2021 | O37: Ghana | P37: Quantitative survey (79 organisations; PLS-SEM) | Q37: Journal | R37: ART-033_Adjei_2021.pdf | S37: new | T37: BORDERLINE: uses institutional theory, not TOE, and studies organisations generally, not only SMEs.
A38: ART-034 | B38: Milhem et al., 2025 | C38: An integrated adoption model of cloud computing-based human resource management by SMEs in developing countries: Evidence from Bahrain | D38: Frontiers | E38: Included | F38: N/A - Included | G38: Yes | H38: Yes | I38: Yes | J38: Yes | K38: Yes | L38: =COUNTIF(G38:K38,"Yes") -> 5 | M38: =IF(L38>=4,"High",IF(L38=3,"Moderate","Low")) -> High | N38: 2025 | O38: Bahrain | P38: Quantitative survey (280 respondents; PLS-SEM) | Q38: Journal | R38: ART-034_Milhem_2025.pdf | S38: new | T38: Bahrain is a high-income country.
A39: ART-035 | B39: Lutfi, 2022 | C39: Understanding the intention to adopt cloud-based accounting information system in Jordanian SMEs | D39: ResearchGate | E39: Included | F39: N/A - Included | G39: Yes | H39: Yes | I39: Yes | J39: Yes | K39: Yes | L39: =COUNTIF(G39:K39,"Yes") -> 5 | M39: =IF(L39>=4,"High",IF(L39=3,"Moderate","Low")) -> High | N39: 2022 | O39: Jordan | P39: Quantitative survey (156 owners/managers) | Q39: Journal | R39: ART-035_Lutfi_2022.pdf | S39: new | T39: Cloud accounting (SaaS).
A40: ART-036 | B40: Andanawarih, Mila & Novitaningrum, 2026 | C40: Antecedents of cloud accounting adoption and its consequences on SME performance: A TOE framework approach | D40: Open-access journal site | E40: Included | F40: N/A - Included | G40: Yes | H40: Yes | I40: Yes | J40: Yes | K40: Yes | L40: =COUNTIF(G40:K40,"Yes") -> 5 | M40: =IF(L40>=4,"High",IF(L40=3,"Moderate","Low")) -> High | N40: 2026 | O40: Indonesia | P40: Quantitative survey (250 MSMEs; PLS-SEM) | Q40: Journal | R40: ART-036_Andanawarih_2026.pdf | S40: new | T40: Cloud accounting (SaaS).
A41: ART-037 | B41: Subramaniam & Teh, 2026 | C41: Accelerating digital transformation: Key drivers of cloud computing adoption and firm performance outcomes in Malaysian SMEs | D41: SpringerLink | E41: Included | F41: N/A - Included | G41: Yes | H41: Yes | I41: Yes | J41: Yes | K41: Yes | L41: =COUNTIF(G41:K41,"Yes") -> 5 | M41: =IF(L41>=4,"High",IF(L41=3,"Moderate","Low")) -> High | N41: 2026 | O41: Malaysia | P41: Quantitative survey (350 SMEs; PLS-SEM) | Q41: Journal | R41: ART-037_Subramaniam_2026.pdf | S41: new | T41: Cost-effectiveness and complexity were NOT significant.
...

Sheet Data Extraction Matrix
A1: DATA EXTRACTION MATRIX
A2: Each quotation is copied verbatim from the PDF and was machine-checked against the file text on 5 Oct 2026. Page numbers are PDF page numbers, not journal page numbers.
A4: Article ID | B4: Author(s) & Year | C4: TOE Context Dimension | D4: Key Theme / Finding | E4: Direct Paragraph / Text Extracted | F4: Reason for Selection / How it Answers RQ | G4: POPIA Discussed? | H4: Load Shedding / Power Discussed? | I4: Local File Path / Folder Location | J4: Reviewer Notes
A5: ART-001 | B5: Aligarh, Sutopo & Widarjo, 2023 | C5: All three | D5: Relative advantage, readiness and competitor pressure drive adoption | E5: PDF p.2: 'relative advantage, organizational readiness, bandwagon effect, competitor pressure, computer self-efficacy, and computer anxiety significantly influence the adoption of cloud computing' | F5: Answers RQ1–RQ3 | G5: No | H5: No | I5: /Articles/ART-001_Aligarh_2023.pdf | J5: Author corrected from "Santos et al." to match the PDF.
A6: ART-002 | B6: Abu Bakar et al., 2024 | C6: Organisational | D6: Financial constraints and weak digital culture hinder adoption | E6: PDF p.1: 'is hindered by various challenges such as financial constraints, maintenance costs, and a lack of digital culture and awareness' | F6: Answers RQ2 | G6: No | H6: No | I6: /Articles/ART-002_AbuBakar_2024.pdf | J6: Source corrected: JOIV is not an MDPI journal.
A7: ART-003 | B7: Al-Dwairi, Al-Tweit & Zyout, 2018 | C7: Technological | D7: Need, cost, security and reliability are the major factors | E7: PDF p.1: 'need, cost, security, and reliability are major factors that impact cloud computing adoption' | F7: Answers RQ1 | G7: No | H7: No | I7: /Articles/ART-003_AlDwairi_2018.pdf | J7: PRE-2020. Author/year corrected from "Yaseen et al., 2023" to match the PDF (ICIEB 2018).
A8: ART-004 | B8: Mokwena & Fatoki, 2024 | C8: Technological | D8: Most SMEs have not adopted cloud; still use traditional IT | E8: PDF p.5: 'The results reveal that the majority of SMEs in the study area have not yet adopted cloud computing for running their businesses' | F8: Answers RQ1, RQ2 | G8: No | H8: No | I8: /Articles/ART-004_Mokwena_2024.pdf | J8: Author corrected from "Mokwena & Sithole".
A9: ART-005 | B9: Mkhize et al., 2025 | C9: All three | D9: Management support is the leading driver; cost and security are barriers | E9: PDF p.1: 'Key adoption drivers include management support (cited by 68% of studies), service quality (56%), and perceived risks (54%)' | F9: Answers RQ1, RQ2 | G9: No | H9: No | I9: /Articles/ART-005_Mkhize_2025.pdf
A10: ART-006 | B10: Sithole & Ruhode, 2021 | C10: All three | D10: Relative advantage important; regulatory support a barrier | E10: PDF p.1: 'relative advantage is an important factor in the consideration of cloud computing adoption by SMMEs, while government and regulatory support is perceived as a barrier' | F10: Answers RQ1–RQ3 | G10: No | H10: No | I10: /Articles/ART-006_Sithole_2021.pdf | J10: POPIA is not mentioned in the PDF (earlier tracker said Yes).
A11: ART-007 | B11: Mhlongo et al., 2024 | C11: Environmental | D11: Infrastructure, data security and skills gaps | E11: PDF p.1: 'including issues related to infrastructure, data security, and skill gaps' | F11: Answers RQ2, RQ3 | G11: No | H11: No | I11: /Articles/ART-007_Mhlongo_2024.pdf
A12: ART-008 | B12: Ilahi et al., 2024 | C12: All three | D12: Four key TOE determinants | E12: PDF p.1: 'relative advantage, top management support, technical readiness, and competitive pressure' | F12: Answers RQ1–RQ3 | G12: No | H12: No | I12: /Articles/ART-008_Ilahi_2024.pdf | J12: Source corrected: not a ScienceDirect journal.
A13: ART-009 | B13: Ahmad, Mahomed & Hashim, 2025 | C13: Technological | D13: Research on SME cloud service models is growing fast | E13: PDF p.1: 'Findings indicate a significant surge in publications, reaching a peak of 140 articles in 2024' | F13: Answers RQ1 | G13: No | H13: No | I13: /Articles/ART-009_Ahmad_2025.pdf
A14: ART-010 | B14: Jayeola et al., 2022 | C14: All three | D14: Cost savings is the most important factor | E14: PDF p.1: 'Asia recorded the highest number of studies, whereas cost savings is the most important adoption factor' | F14: Answers RQ1, RQ2 | G14: No | H14: No | I14: /Articles/ART-010_Jayeola_2022.pdf
A15: ART-011 | B15: Khayer, Jahan, Hossain & Hossain, 2020 | C15: Technological | D15: Effort expectancy, security and trust predict adoption | E15: PDF p.1: 'performance expectancy; effort expectancy; absorptive capacity; data security and privacy; and perceived trust' | F15: Answers RQ1, RQ2 | G15: No | H15: No | I15: /Articles/ART-011_Khayer_2020a.pdf | J15: Published online 2020; issue 51(1) dated 2021.
A16: ART-012 | B16: Skafi, Yunis & Zekri, 2020 | C16: Environmental | D16: Poor infrastructure and weak government support reduce adoption | E16: PDF p.1: 'poor infrastructure and lack of government initiatives) are negatively related to the adoption decision' | F16: Answers RQ1–RQ3 | G16: No | H16: Brief | I16: /Articles/ART-012_Skafi_2020.pdf
A17: ART-013 | B17: Shetty & Panda, 2021 | C17: Technological | D17: Cost and flexibility are central | E17: PDF p.1: 'Findings highlight the applicability of influential factors such as' | F17: Answers RQ1, RQ3 | G17: No | H17: No | I17: /Articles/ART-013_Shetty_2021.pdf
A18: ART-014 | B18: Picoto, Crespo & Carvalho, 2021 | C18: Technological | D18: Convenience, compatibility and organisational confidence drive cloud use | E18: PDF p.1: 'The results indicate that convenience, compatibility, and organizational confidence are significant antecedents of the use of cloud computing' | F18: Answers RQ1, RQ2 | G18: No | H18: No | I18: /Articles/ART-014_Picoto_2021.pdf | J18: BORDERLINE: Portugal is a high-income country and the sample is organisations, not only SMEs. Correct PDF now in folder.
A19: ART-015 | B19: Salleh, Hussin & Suhaimi, 2018 | C19: Technological | D19: Post-adoption impacts are under-studied | E19: PDF p.1: 'A total of 39 relevant articles were reviewed' | F19: Answers RQ1 | G19: No | H19: No | I19: /Articles/ART-015_Salleh_2018.pdf | J19: PRE-2020.
A20: ART-016 | B20: Nuskiya, 2017 | C20: Organisational | D20: Top management support and technology readiness | E20: PDF p.1: 'The significant impact was identified to adopt the cloud computing is top management support and technology readiness' | F20: Answers RQ2 | G20: No | H20: No | I20: /Articles/ART-016_Nuskiya_2017.pdf | J20: PRE-2020.
A21: ART-017 | B21: Abubakar, Bass & Allison, 2014 | C21: Environmental | D21: Adopters are less concerned with security; power is an issue | E21: PDF p.1: 'these SMEs are less concerned with challenges like security, privacy and data loss' | F21: Answers RQ2, RQ3 | G21: No | H21: Yes | I21: /Articles/ART-017_Abubakar_2014.pdf | J21: PRE-2020. Electricity discussed.
A22: ART-018 | B22: Modisane & Jokonya, 2021 | C22: All three | D22: Technological context has a positive significant effect | E22: PDF p.8: 'technological context has a positive significant effect on the adoption of cloud computing practices' | F22: Answers RQ1–RQ3 | G22: No | H22: No | I22: /Articles/ART-018_Modisane_2021.pdf | J22: POPIA and electricity are not mentioned in the PDF (earlier tracker said Yes).
A23: ART-019 | B23: Mohlameane & Ruxwana, 2020 | C23: Environmental | D23: POPI Act only partly applies to cloud computing | E23: PDF p.7: 'over 90% of participants viewed the POPI Act as a policy that has an impact on cloud computing' | F23: Answers RQ1, RQ3 | G23: Yes | H23: No | I23: /Articles/ART-019_Mohlameane_2020.pdf | J23: The only included study that discusses POPIA.
A24: ART-020 | B24: Mudzamba, van der Schyff & Renaud, 2022 | C24: Organisational | D24: Technical expertise is vital; SMEs skip preparatory activities | E24: PDF p.1: 'Our findings indicate that technical expertise (i.e., knowledge) amongst SMEs plays a vital role in the cloud adoption process' | F24: Answers RQ2 | G24: No | H24: No | I24: /Articles/ART-020_Mudzamba_2022.pdf
A25: ART-021 | B25: Morema, Adeyelure & Seaba, 2026 | C25: All three | D25: Top management support strongest; load shedding named as operational reality | E25: PDF p.7: 'top management support (β = 0.466)' | F25: Answers RQ2, RQ3 | G25: No | H25: Yes | I25: /Articles/ART-021_Morema_2026.pdf | J25: Load shedding is mentioned once. The PDF is a browser print with the right edge cut off: download the proper PDF and re-check the quote.
A26: ART-022 | B26: Buhari, Muhammad, Bodinga & Sifawa, 2022 | C26: Organisational | D26: Lack of encouragement, training and executive sponsorship | E26: PDF p.1: 'lack of encouragement, poor training, application is missing and lack of executive sponsorship' | F26: Answers RQ2 | G26: No | H26: No | I26: /Articles/ART-022_Buhari_2022.pdf | J26: TOE is mentioned only briefly (3 times).
A27: ART-023 | B27: Gui et al., 2020 | C27: Organisational | D27: Top management and relative advantage have positive impact | E27: PDF p.1: 'top management encouragement and relative advantages have a positive impact on the adoption of cloud computing in MSMEs in Indonesia' | F27: Answers RQ1, RQ2 | G27: No | H27: No | I27: /Articles/ART-023_Gui_2020.pdf | J27: Year taken from the PDF creation date (Dec 2020); confirm volume/issue on the JOIV site.
A28: ART-024 | B28: Al-Sharafi et al., 2023 | C28: All three | D28: Six TOE factors significant; complexity ranked first | E28: PDF p.1: 'relative advantage, complexity, compatibility, top management support, cost reduction, and government support significantly affect cloud computing integration' | F28: Answers RQ1–RQ3 | G28: No | H28: No | I28: /Articles/ART-024_AlSharafi_2023.pdf
A29: ART-025 | B29: Khayer, Talukder, Bao & Hossain, 2020 | C29: Technological | D29: Server location is the strongest predictor | E29: PDF p.1: 'the most significant predictor of cloud adoption is server location followed by facilitating conditions, relative advantage, service quality, top management support' | F29: Answers RQ1, RQ2 | G29: No | H29: No | I29: /Articles/ART-025_Khayer_2020b.pdf | J29: Server location finding is relevant to data sovereignty.
A30: ART-026 | B30: Alamri & Alzahrani, 2024 | C30: All three | D30: TOE analysis of e-commerce SME adoption | E30: PDF p.1: 'analyzing the technological, organizational, and environmental factors that affect cloud service adoption' | F30: Answers RQ1–RQ3 | G30: No | H30: No | I30: /Articles/ART-026_Alamri_2024.pdf | J30: Saudi Arabia is a high-income country.
A31: ART-027 | B31: Mujalli et al., 2024 | C31: All three | D31: TOE factors plus mimetic and normative pressure | E31: PDF p.1: 'organizational resources, employee capability, top senior management support, mimetic pressures, normative pressures' | F31: Answers RQ1–RQ3 | G31: No | H31: No | I31: /Articles/ART-027_Mujalli_2024.pdf | J31: Cloud accounting (SaaS). Saudi Arabia is a high-income country.
A32: ART-028 | B32: Sayginer & Ercan, 2021 | C32: Organisational | D32: Top management support and complexity explain 29.8% | E32: PDF p.1 (OCR): 'top management support and complexity explained 29.8%' | F32: Answers RQ1, RQ2 | G32: No | H32: No | I32: /Articles/ART-028_Sayginer_2021.pdf | J32: Scanned PDF: quote read by OCR, check it by eye.
A33: ART-029 | B33: Nosheen, Omar & Hashim, 2025 | C33: Technological | D33: Privacy, legal compliance and security obstruct SaaS adoption | E33: PDF p.1: 'beset by numerous obstacles, like data privacy, legal compliance and security concerns' | F33: Answers RQ1, RQ3 | G33: No | H33: No | I33: /Articles/ART-029_Nosheen_2025.pdf
A34: ART-030 | B34: Sastararuji et al., 2021 | C34: All three | D34: Five determinant groups incl. vendor and owner | E34: PDF p.1: 'technology, organization, environment, vendor, and owner that influence the adoption decision' | F34: Answers RQ4 | G34: No | H34: No | I34: /Articles/ART-030_Sastararuji_2021.pdf | J34: Conceptual paper: MMAT criteria 3–4 marked "Can't tell".
A35: ART-031 | B35: Ali, Hassan, Abdullahi & Abdulah, 2023 | C35: All three | D35: Cost savings, firm size, management and regulatory support significant | E35: PDF p.1: 'cost savings, firm size, top management support, and regulatory support significantly influence CC adoption in SMEs' | F35: Answers RQ1–RQ3 | G35: No | H35: No | I35: /Articles/ART-031_Ali_2023.pdf | J35: Security and competitive pressure were NOT significant.
A36: ART-032 | B36: Ognjanović, Šendelj, Daković-Tadić & Kožuh, 2024 | C36: Technological | D36: Attitudes shifted 2017–2023; security and expertise key | E36: PDF p.1: 'The findings revealed substantial shifts in SME attitudes towards cloud computing' | F36: Answers RQ1, RQ2 | G36: No | H36: No | I36: /Articles/ART-032_Ognjanovic_2024.pdf
A37: ART-033 | B37: Adjei, Adams & Mamattah, 2021 | C37: Environmental | D37: Institutional pressures explain 27% of adoption | E37: PDF p.1: 'explain 27% of the variance in cloud computing adoption' | F37: Answers RQ3 | G37: No | H37: No | I37: /Articles/ART-033_Adjei_2021.pdf | J37: BORDERLINE: uses institutional theory, not TOE, and studies organisations generally, not only SMEs.
A38: ART-034 | B38: Milhem et al., 2025 | C38: All three | D38: All three TOE contexts significant | E38: PDF p.1: 'technological, organizational, and environmental contexts greatly impact the adoption of sustainable cloud computing-based HRM' | F38: Answers RQ1–RQ3 | G38: No | H38: No | I38: /Articles/ART-034_Milhem_2025.pdf | J38: Bahrain is a high-income country.
A39: ART-035 | B39: Lutfi, 2022 | C39: All three | D39: Six TOE factors affect intention | E39: PDF p.1: 'this study applied the Technology, Organization, and Environment model to examine CB-AIS adoption among SMEs in Jordan' | F39: Answers RQ1–RQ3 | G39: No | H39: No | I39: /Articles/ART-035_Lutfi_2022.pdf | J39: Cloud accounting (SaaS).
A40: ART-036 | B40: Andanawarih, Mila & Novitaningrum, 2026 | C40: All three | D40: Management support, competitive pressure and bandwagon effect | E40: PDF p.1: 'support from senior management, competitive pressure, the bandwagon effect, and user confidence in their ability to use IT' | F40: Answers RQ2, RQ3 | G40: No | H40: No | I40: /Articles/ART-036_Andanawarih_2026.pdf | J40: Cloud accounting (SaaS).
A41: ART-037 | B41: Subramaniam & Teh, 2026 | C41: All three | D41: Relative advantage, security assurance, competitive pressure | E41: PDF p.1: 'relative advantage, security assurance, industry influence, competitive pressure, corporate culture, and IT competency significantly influence cloud computing adoption' | F41: Answers RQ1–RQ3 | G41: No | H41: No | I41: /Articles/ART-037_Subramaniam_2026.pdf | J41: Cost-effectiveness and complexity were NOT significant.
...

Sheet Summary (40 studies)
A1: PROFILE OF THE 40 INCLUDED STUDIES (counts update automatically from the screening sheet)
A3: Publication year | B3: Count | C3: % of 40
A4: 2014 | B4: =COUNTIF('Article Screening & MMAT'!N$5:N$44,2014) -> 1 | C4: =B4/40 -> 0.025
A5: 2017 | B5: =COUNTIF('Article Screening & MMAT'!N$5:N$44,2017) -> 1 | C5: =B5/40 -> 0.025
A6: 2018 | B6: =COUNTIF('Article Screening & MMAT'!N$5:N$44,2018) -> 2 | C6: =B6/40 -> 0.05
A7: 2020 | B7: =COUNTIF('Article Screening & MMAT'!N$5:N$44,2020) -> 5 | C7: =B7/40 -> 0.125
A8: 2021 | B8: =COUNTIF('Article Screening & MMAT'!N$5:N$44,2021) -> 7 | C8: =B8/40 -> 0.175
A9: 2022 | B9: =COUNTIF('Article Screening & MMAT'!N$5:N$44,2022) -> 4 | C9: =B9/40 -> 0.1
A10: 2023 | B10: =COUNTIF('Article Screening & MMAT'!N$5:N$44,2023) -> 4 | C10: =B10/40 -> 0.1
A11: 2024 | B11: =COUNTIF('Article Screening & MMAT'!N$5:N$44,2024) -> 8 | C11: =B11/40 -> 0.2
A12: 2025 | B12: =COUNTIF('Article Screening & MMAT'!N$5:N$44,2025) -> 5 | C12: =B12/40 -> 0.125
A13: 2026 | B13: =COUNTIF('Article Screening & MMAT'!N$5:N$44,2026) -> 3 | C13: =B13/40 -> 0.075
A14: Total | B14: =SUM(B4:B13) -> 40
A16: Source database / platform | B16: Count | C16: % of 40
A17: ACM Digital Library | B17: =COUNTIF('Article Screening & MMAT'!D$5:D$44,"ACM Digital Library") -> 2 | C17: =B17/40 -> 0.05
A18: Frontiers | B18: =COUNTIF('Article Screening & MMAT'!D$5:D$44,"Frontiers") -> 1 | C18: =B18/40 -> 0.025
A19: Google Scholar | B19: =COUNTIF('Article Screening & MMAT'!D$5:D$44,"Google Scholar") -> 7 | C19: =B19/40 -> 0.175
A20: IEEE Xplore | B20: =COUNTIF('Article Screening & MMAT'!D$5:D$44,"IEEE Xplore") -> 2 | C20: =B20/40 -> 0.05
A21: MDPI | B21: =COUNTIF('Article Screening & MMAT'!D$5:D$44,"MDPI") -> 2 | C21: =B21/40 -> 0.05
A22: Open-access journal site | B22: =COUNTIF('Article Screening & MMAT'!D$5:D$44,"Open-access journal site") -> 11 | C22: =B22/40 -> 0.275
A23: PubMed Central | B23: =COUNTIF('Article Screening & MMAT'!D$5:D$44,"PubMed Central") -> 1 | C23: =B23/40 -> 0.025
A24: ResearchGate | B24: =COUNTIF('Article Screening & MMAT'!D$5:D$44,"ResearchGate") -> 3 | C24: =B24/40 -> 0.075
A25: SciELO | B25: =COUNTIF('Article Screening & MMAT'!D$5:D$44,"SciELO") -> 1 | C25: =B25/40 -> 0.025
A26: ScienceDirect | B26: =COUNTIF('Article Screening & MMAT'!D$5:D$44,"ScienceDirect") -> 4 | C26: =B26/40 -> 0.1
A27: Scopus | B27: =COUNTIF('Article Screening & MMAT'!D$5:D$44,"Scopus") -> 3 | C27: =B27/40 -> 0.075
A28: SpringerLink | B28: =COUNTIF('Article Screening & MMAT'!D$5:D$44,"SpringerLink") -> 1 | C28: =B28/40 -> 0.025
A29: Wiley Online Library | B29: =COUNTIF('Article Screening & MMAT'!D$5:D$44,"Wiley Online Library") -> 2 | C29: =B29/40 -> 0.05
A30: Total | B30: =SUM(B17:B29) -> 40
A32: Publication channel | B32: Count | C32: % of 40
A33: Conference | B33: =COUNTIF('Article Screening & MMAT'!Q$5:Q$44,"Conference") -> 5 | C33: =B33/40 -> 0.125
A34: Journal | B34: =COUNTIF('Article Screening & MMAT'!Q$5:Q$44,"Journal") -> 35 | C34: =B34/40 -> 0.875
A35: Total | B35: =SUM(B33:B34) -> 40
A37: Country / context | B37: Count | C37: % of 40
A38: Africa | B38: =COUNTIF('Article Screening & MMAT'!O$5:O$44,"Africa") -> 1 | C38: =B38/40 -> 0.025
A39: Bahrain | B39: =COUNTIF('Article Screening & MMAT'!O$5:O$44,"Bahrain") -> 1 | C39: =B39/40 -> 0.025
A40: Bangladesh | B40: =COUNTIF('Article Screening & MMAT'!O$5:O$44,"Bangladesh") -> 2 | C40: =B40/40 -> 0.05
A41: Ghana | B41: =COUNTIF('Article Screening & MMAT'!O$5:O$44,"Ghana") -> 1 | C41: =B41/40 -> 0.025
A42: Global review | B42: =COUNTIF('Article Screening & MMAT'!O$5:O$44,"Global review") -> 6 | C42: =B42/40 -> 0.15
A43: Indonesia | B43: =COUNTIF('Article Screening & MMAT'!O$5:O$44,"Indonesia") -> 4 | C43: =B43/40 -> 0.1
A44: Jordan | B44: =COUNTIF('Article Screening & MMAT'!O$5:O$44,"Jordan") -> 2 | C44: =B44/40 -> 0.05
...
